Workbook

Sheet PANEL COMPRAS
A1: PANEL DE COMPRAS -- MARINAFISK PESCADOS | N1: AUX PROVEEDORES (no borrar) | O1: -- TODOS LOS PROVEEDORES -- | S1: AUX PRODUCTOS (no borrar) | T1: -- TODOS LOS ARTICULOS -- | X1: AUX SELECTOR (no borrar)
N2: =PROVEEDORES!A3 -> 50001 | O2: =PROVEEDORES!B3 -> COPESA | P2: =IF(N2<>"",SUMIFS(COMPRAS!$J$3:$J$4997,COMPRAS!$D$3:$D$4997,N2,COMPRAS!$B$3:$B$4997,">="&IF($C$4="",DATE(1900,1,1),$C$4),COMPRAS!$B$3:$B$4997,"<="&IF($F$4="",DATE(2999,12,31),$F$4)),0) -> 18026.85 | Q2: =IF(N2<>"",SUMIFS(COMPRAS!$O$3:$O$4997,COMPRAS!$D$3:$D$4997,N2,COMPRAS!$B$3:$B$4997,">="&IF($C$4="",DATE(1900,1,1),$C$4),COMPRAS!$B$3:$B$4997,"<="&IF($F$4="",DATE(2999,12,31),$F$4)),0) -> 81085.323 | S2: =PRODUCTOS!A3 -> 0 | T2: =PRODUCTOS!B3 -> 0 | U2: =IF(S2<>"",SUMIFS(COMPRAS!$J$3:$J$4997,COMPRAS!$G$3:$G$4997,S2,COMPRAS!$B$3:$B$4997,">="&IF($C$4="",DATE(1900,1,1),$C$4),COMPRAS!$B$3:$B$4997,"<="&IF($F$4="",DATE(2999,12,31),$F$4)),0) -> 0 | V2: =IF(S2<>"",SUMIFS(COMPRAS!$O$3:$O$4997,COMPRAS!$G$3:$G$4997,S2,COMPRAS!$B$3:$B$4997,">="&IF($C$4="",DATE(1900,1,1),$C$4),COMPRAS!$B$3:$B$4997,"<="&IF($F$4="",DATE(2999,12,31),$F$4)),0) -> 0 | X2: =IF($B$45="-- TODOS LOS PROVEEDORES --","TODOS",IFERROR(INDEX($N$1:$N$206,MATCH($B$45,$O$1:$O$206,0)),"")) -> TODOS | Y2: =IF($X$2="TODOS",U2,IF(S2<>"",SUMIFS(COMPRAS!$J$3:$J$4997,COMPRAS!$G$3:$G$4997,S2,COMPRAS!$D$3:$D$4997,$X$2,COMPRAS!$B$3:$B$4997,">="&IF($C$4="",DATE(1900,1,1),$C$4),COMPRAS!$B$3:$B$4997,"<="&IF($F$4="",DATE(2999,12,31),$F$4)),0)) -> 0 | Z2: =IF($X$2="TODOS",V2,IF(S2<>"",SUMIFS(COMPRAS!$O$3:$O$4997,COMPRAS!$G$3:$G$4997,S2,COMPRAS!$D$3:$D$4997,$X$2,COMPRAS!$B$3:$B$4997,">="&IF($C$4="",DATE(1900,1,1),$C$4),COMPRAS!$B$3:$B$4997,"<="&IF($F$4="",DATE(2999,12,31),$F$4)),0)) -> 0
A3: Se actualiza solo con las compras registradas en la hoja COMPRAS -- no hay que tocar nada a mano. | N3: =PROVEEDORES!A4 -> 50010 | O3: =PROVEEDORES!B4 -> PERFECTO MONTERO | P3: =IF(N3<>"",SUMIFS(COMPRAS!$J$3:$J$4997,COMPRAS!$D$3:$D$4997,N3,COMPRAS!$B$3:$B$4997,">="&IF($C$4="",DATE(1900,1,1),$C$4),COMPRAS!$B$3:$B$4997,"<="&IF($F$4="",DATE(2999,12,31),$F$4)),0) -> 2834.25 | Q3: =IF(N3<>"",SUMIFS(COMPRAS!$O$3:$O$4997,COMPRAS!$D$3:$D$4997,N3,COMPRAS!$B$3:$B$4997,">="&IF($C$4="",DATE(1900,1,1),$C$4),COMPRAS!$B$3:$B$4997,"<="&IF($F$4="",DATE(2999,12,31),$F$4)),0) -> 15098.976 | S3: =PRODUCTOS!A4 -> 0 | T3: =PRODUCTOS!B4 -> 0 | U3: =IF(S3<>"",SUMIFS(COMPRAS!$J$3:$J$4997,COMPRAS!$G$3:$G$4997,S3,COMPRAS!$B$3:$B$4997,">="&IF($C$4="",DATE(1900,1,1),$C$4),COMPRAS!$B$3:$B$4997,"<="&IF($F$4="",DATE(2999,12,31),$F$4)),0) -> 0 | V3: =IF(S3<>"",SUMIFS(COMPRAS!$O$3:$O$4997,COMPRAS!$G$3:$G$4997,S3,COMPRAS!$B$3:$B$4997,">="&IF($C$4="",DATE(1900,1,1),$C$4),COMPRAS!$B$3:$B$4997,"<="&IF($F$4="",DATE(2999,12,31),$F$4)),0) -> 0 | X3: =IF(OR($B$46="",$B$46="-- TODOS LOS ARTICULOS --"),"*",IFERROR(INDEX($S$1:$S$231,MATCH($B$46,$T$1:$T$231,0)),"*")) -> * | Y3: =IF($X$2="TODOS",U3,IF(S3<>"",SUMIFS(COMPRAS!$J$3:$J$4997,COMPRAS!$G$3:$G$4997,S3,COMPRAS!$D$3:$D$4997,$X$2,COMPRAS!$B$3:$B$4997,">="&IF($C$4="",DATE(1900,1,1),$C$4),COMPRAS!$B$3:$B$4997,"<="&IF($F$4="",DATE(2999,12,31),$F$4)),0)) -> 0 | Z3: =IF($X$2="TODOS",V3,IF(S3<>"",SUMIFS(COMPRAS!$O$3:$O$4997,COMPRAS!$G$3:$G$4997,S3,COMPRAS!$D$3:$D$4997,$X$2,COMPRAS!$B$3:$B$4997,">="&IF($C$4="",DATE(1900,1,1),$C$4),COMPRAS!$B$3:$B$4997,"<="&IF($F$4="",DATE(2999,12,31),$F$4)),0)) -> 0
A4: Filtrar por fecha -- Desde: | E4: Hasta: | H4: (vacio = todas las fechas) | N4: =PROVEEDORES!A5 -> 50019 | O4: =PROVEEDORES!B5 -> ANGELITA VILLAR | P4: =IF(N4<>"",SUMIFS(COMPRAS!$J$3:$J$4997,COMPRAS!$D$3:$D$4997,N4,COMPRAS!$B$3:$B$4997,">="&IF($C$4="",DATE(1900,1,1),$C$4),COMPRAS!$B$3:$B$4997,"<="&IF($F$4="",DATE(2999,12,31),$F$4)),0) -> 205.1 | Q4: =IF(N4<>"",SUMIFS(COMPRAS!$O$3:$O$4997,COMPRAS!$D$3:$D$4997,N4,COMPRAS!$B$3:$B$4997,">="&IF($C$4="",DATE(1900,1,1),$C$4),COMPRAS!$B$3:$B$4997,"<="&IF($F$4="",DATE(2999,12,31),$F$4)),0) -> 1402.2348 | S4: =PRODUCTOS!A5 -> 0 | T4: =PRODUCTOS!B5 -> 0 | U4: =IF(S4<>"",SUMIFS(COMPRAS!$J$3:$J$4997,COMPRAS!$G$3:$G$4997,S4,COMPRAS!$B$3:$B$4997,">="&IF($C$4="",DATE(1900,1,1),$C$4),COMPRAS!$B$3:$B$4997,"<="&IF($F$4="",DATE(2999,12,31),$F$4)),0) -> 0 | V4: =IF(S4<>"",SUMIFS(COMPRAS!$O$3:$O$4997,COMPRAS!$G$3:$G$4997,S4,COMPRAS!$B$3:$B$4997,">="&IF($C$4="",DATE(1900,1,1),$C$4),COMPRAS!$B$3:$B$4997,"<="&IF($F$4="",DATE(2999,12,31),$F$4)),0) -> 0 | Y4: =IF($X$2="TODOS",U4,IF(S4<>"",SUMIFS(COMPRAS!$J$3:$J$4997,COMPRAS!$G$3:$G$4997,S4,COMPRAS!$D$3:$D$4997,$X$2,COMPRAS!$B$3:$B$4997,">="&IF($C$4="",DATE(1900,1,1),$C$4),COMPRAS!$B$3:$B$4997,"<="&IF($F$4="",DATE(2999,12,31),$F$4)),0)) -> 0 | Z4: =IF($X$2="TODOS",V4,IF(S4<>"",SUMIFS(COMPRAS!$O$3:$O$4997,COMPRAS!$G$3:$G$4997,S4,COMPRAS!$D$3:$D$4997,$X$2,COMPRAS!$B$3:$B$4997,">="&IF($C$4="",DATE(1900,1,1),$C$4),COMPRAS!$B$3:$B$4997,"<="&IF($F$4="",DATE(2999,12,31),$F$4)),0)) -> 0
A5: TOP 15 PROVEEDORES -- MAS KILOS COMPRADOS | E5: TOP 15 PROVEEDORES -- MAS IMPORTE COMPRADO | N5: =PROVEEDORES!A6 -> 50020 | O5: =PROVEEDORES!B6 -> PACO MOINELO | P5: =IF(N5<>"",SUMIFS(COMPRAS!$J$3:$J$4997,COMPRAS!$D$3:$D$4997,N5,COMPRAS!$B$3:$B$4997,">="&IF($C$4="",DATE(1900,1,1),$C$4),COMPRAS!$B$3:$B$4997,"<="&IF($F$4="",DATE(2999,12,31),$F$4)),0) -> 1761.55 | Q5: =IF(N5<>"",SUMIFS(COMPRAS!$O$3:$O$4997,COMPRAS!$D$3:$D$4997,N5,COMPRAS!$B$3:$B$4997,">="&IF($C$4="",DATE(1900,1,1),$C$4),COMPRAS!$B$3:$B$4997,"<="&IF($F$4="",DATE(2999,12,31),$F$4)),0) -> 10973.989 | S5: =PRODUCTOS!A6 -> 0 | T5: =PRODUCTOS!B6 -> 0 | U5: =IF(S5<>"",SUMIFS(COMPRAS!$J$3:$J$4997,COMPRAS!$G$3:$G$4997,S5,COMPRAS!$B$3:$B$4997,">="&IF($C$4="",DATE(1900,1,1),$C$4),COMPRAS!$B$3:$B$4997,"<="&IF($F$4="",DATE(2999,12,31),$F$4)),0) -> 0 | V5: =IF(S5<>"",SUMIFS(COMPRAS!$O$3:$O$4997,COMPRAS!$G$3:$G$4997,S5,COMPRAS!$B$3:$B$4997,">="&IF($C$4="",DATE(1900,1,1),$C$4),COMPRAS!$B$3:$B$4997,"<="&IF($F$4="",DATE(2999,12,31),$F$4)),0) -> 0 | Y5: =IF($X$2="TODOS",U5,IF(S5<>"",SUMIFS(COMPRAS!$J$3:$J$4997,COMPRAS!$G$3:$G$4997,S5,COMPRAS!$D$3:$D$4997,$X$2,COMPRAS!$B$3:$B$4997,">="&IF($C$4="",DATE(1900,1,1),$C$4),COMPRAS!$B$3:$B$4997,"<="&IF($F$4="",DATE(2999,12,31),$F$4)),0)) -> 0 | Z5: =IF($X$2="TODOS",V5,IF(S5<>"",SUMIFS(COMPRAS!$O$3:$O$4997,COMPRAS!$G$3:$G$4997,S5,COMPRAS!$D$3:$D$4997,$X$2,COMPRAS!$B$3:$B$4997,">="&IF($C$4="",DATE(1900,1,1),$C$4),COMPRAS!$B$3:$B$4997,"<="&IF($F$4="",DATE(2999,12,31),$F$4)),0)) -> 0
A6: # | B6: Proveedor | C6: Kilos | E6: # | F6: Proveedor | G6: Importe | N6: =PROVEEDORES!A7 -> 50034 | O6: =PROVEEDORES!B7 -> MANUEL CEBREIRA MELLA | P6: =IF(N6<>"",SUMIFS(COMPRAS!$J$3:$J$4997,COMPRAS!$D$3:$D$4997,N6,COMPRAS!$B$3:$B$4997,">="&IF($C$4="",DATE(1900,1,1),$C$4),COMPRAS!$B$3:$B$4997,"<="&IF($F$4="",DATE(2999,12,31),$F$4)),0) -> 0 | Q6: =IF(N6<>"",SUMIFS(COMPRAS!$O$3:$O$4997,COMPRAS!$D$3:$D$4997,N6,COMPRAS!$B$3:$B$4997,">="&IF($C$4="",DATE(1900,1,1),$C$4),COMPRAS!$B$3:$B$4997,"<="&IF($F$4="",DATE(2999,12,31),$F$4)),0) -> 0 | S6: =PRODUCTOS!A7 -> 0 | T6: =PRODUCTOS!B7 -> 0 | U6: =IF(S6<>"",SUMIFS(COMPRAS!$J$3:$J$4997,COMPRAS!$G$3:$G$4997,S6,COMPRAS!$B$3:$B$4997,">="&IF($C$4="",DATE(1900,1,1),$C$4),COMPRAS!$B$3:$B$4997,"<="&IF($F$4="",DATE(2999,12,31),$F$4)),0) -> 0 | V6: =IF(S6<>"",SUMIFS(COMPRAS!$O$3:$O$4997,COMPRAS!$G$3:$G$4997,S6,COMPRAS!$B$3:$B$4997,">="&IF($C$4="",DATE(1900,1,1),$C$4),COMPRAS!$B$3:$B$4997,"<="&IF($F$4="",DATE(2999,12,31),$F$4)),0) -> 0 | Y6: =IF($X$2="TODOS",U6,IF(S6<>"",SUMIFS(COMPRAS!$J$3:$J$4997,COMPRAS!$G$3:$G$4997,S6,COMPRAS!$D$3:$D$4997,$X$2,COMPRAS!$B$3:$B$4997,">="&IF($C$4="",DATE(1900,1,1),$C$4),COMPRAS!$B$3:$B$4997,"<="&IF($F$4="",DATE(2999,12,31),$F$4)),0)) -> 0 | Z6: =IF($X$2="TODOS",V6,IF(S6<>"",SUMIFS(COMPRAS!$O$3:$O$4997,COMPRAS!$G$3:$G$4997,S6,COMPRAS!$D$3:$D$4997,$X$2,COMPRAS!$B$3:$B$4997,">="&IF($C$4="",DATE(1900,1,1),$C$4),COMPRAS!$B$3:$B$4997,"<="&IF($F$4="",DATE(2999,12,31),$F$4)),0)) -> 0
A7: 1 | B7: =IFERROR(INDEX($O$2:$O$206,MATCH(LARGE($P$2:$P$206,1),$P$2:$P$206,0)),"") -> XESTION NOVA LONXA RIVEIRA S.L. | C7: =IFERROR(LARGE($P$2:$P$206,1),0) -> 41663.771 | E7: 1 | F7: =IFERROR(INDEX($O$2:$O$206,MATCH(LARGE($Q$2:$Q$206,1),$Q$2:$Q$206,0)),"") -> XESTION NOVA LONXA RIVEIRA S.L. | G7: =IFERROR(LARGE($Q$2:$Q$206,1),0) -> 101872.87 | N7: =PROVEEDORES!A8 -> 50035 | O7: =PROVEEDORES!B8 -> SCANFISK SEAFFOD S,L | P7: =IF(N7<>"",SUMIFS(COMPRAS!$J$3:$J$4997,COMPRAS!$D$3:$D$4997,N7,COMPRAS!$B$3:$B$4997,">="&IF($C$4="",DATE(1900,1,1),$C$4),COMPRAS!$B$3:$B$4997,"<="&IF($F$4="",DATE(2999,12,31),$F$4)),0) -> 4941.7 | Q7: =IF(N7<>"",SUMIFS(COMPRAS!$O$3:$O$4997,COMPRAS!$D$3:$D$4997,N7,COMPRAS!$B$3:$B$4997,">="&IF($C$4="",DATE(1900,1,1),$C$4),COMPRAS!$B$3:$B$4997,"<="&IF($F$4="",DATE(2999,12,31),$F$4)),0) -> 35388.74 | S7: =PRODUCTOS!A8 -> 0 | T7: =PRODUCTOS!B8 -> 0 | U7: =IF(S7<>"",SUMIFS(COMPRAS!$J$3:$J$4997,COMPRAS!$G$3:$G$4997,S7,COMPRAS!$B$3:$B$4997,">="&IF($C$4="",DATE(1900,1,1),$C$4),COMPRAS!$B$3:$B$4997,"<="&IF($F$4="",DATE(2999,12,31),$F$4)),0) -> 0 | V7: =IF(S7<>"",SUMIFS(COMPRAS!$O$3:$O$4997,COMPRAS!$G$3:$G$4997,S7,COMPRAS!$B$3:$B$4997,">="&IF($C$4="",DATE(1900,1,1),$C$4),COMPRAS!$B$3:$B$4997,"<="&IF($F$4="",DATE(2999,12,31),$F$4)),0) -> 0 | Y7: =IF($X$2="TODOS",U7,IF(S7<>"",SUMIFS(COMPRAS!$J$3:$J$4997,COMPRAS!$G$3:$G$4997,S7,COMPRAS!$D$3:$D$4997,$X$2,COMPRAS!$B$3:$B$4997,">="&IF($C$4="",DATE(1900,1,1),$C$4),COMPRAS!$B$3:$B$4997,"<="&IF($F$4="",DATE(2999,12,31),$F$4)),0)) -> 0 | Z7: =IF($X$2="TODOS",V7,IF(S7<>"",SUMIFS(COMPRAS!$O$3:$O$4997,COMPRAS!$G$3:$G$4997,S7,COMPRAS!$D$3:$D$4997,$X$2,COMPRAS!$B$3:$B$4997,">="&IF($C$4="",DATE(1900,1,1),$C$4),COMPRAS!$B$3:$B$4997,"<="&IF($F$4="",DATE(2999,12,31),$F$4)),0)) -> 0
A8: 2 | B8: =IFERROR(INDEX($O$2:$O$206,MATCH(LARGE($P$2:$P$206,2),$P$2:$P$206,0)),"") -> SUBASTAS CORUÑA S.L. | C8: =IFERROR(LARGE($P$2:$P$206,2),0) -> 18832.8 | E8: 2 | F8: =IFERROR(INDEX($O$2:$O$206,MATCH(LARGE($Q$2:$Q$206,2),$Q$2:$Q$206,0)),"") -> COPESA | G8: =IFERROR(LARGE($Q$2:$Q$206,2),0) -> 81085.323 | N8: =PROVEEDORES!A9 -> 50048 | O8: =PROVEEDORES!B9 -> JOSE LUIS CORREA KESSLER S.L. | P8: =IF(N8<>"",SUMIFS(COMPRAS!$J$3:$J$4997,COMPRAS!$D$3:$D$4997,N8,COMPRAS!$B$3:$B$4997,">="&IF($C$4="",DATE(1900,1,1),$C$4),COMPRAS!$B$3:$B$4997,"<="&IF($F$4="",DATE(2999,12,31),$F$4)),0) -> 15321 | Q8: =IF(N8<>"",SUMIFS(COMPRAS!$O$3:$O$4997,COMPRAS!$D$3:$D$4997,N8,COMPRAS!$B$3:$B$4997,">="&IF($C$4="",DATE(1900,1,1),$C$4),COMPRAS!$B$3:$B$4997,"<="&IF($F$4="",DATE(2999,12,31),$F$4)),0) -> 31840.2 | S8: =PRODUCTOS!A9 -> 0 | T8: =PRODUCTOS!B9 -> 0 | U8: =IF(S8<>"",SUMIFS(COMPRAS!$J$3:$J$4997,COMPRAS!$G$3:$G$4997,S8,COMPRAS!$B$3:$B$4997,">="&IF($C$4="",DATE(1900,1,1),$C$4),COMPRAS!$B$3:$B$4997,"<="&IF($F$4="",DATE(2999,12,31),$F$4)),0) -> 0 | V8: =IF(S8<>"",SUMIFS(COMPRAS!$O$3:$O$4997,COMPRAS!$G$3:$G$4997,S8,COMPRAS!$B$3:$B$4997,">="&IF($C$4="",DATE(1900,1,1),$C$4),COMPRAS!$B$3:$B$4997,"<="&IF($F$4="",DATE(2999,12,31),$F$4)),0) -> 0 | Y8: =IF($X$2="TODOS",U8,IF(S8<>"",SUMIFS(COMPRAS!$J$3:$J$4997,COMPRAS!$G$3:$G$4997,S8,COMPRAS!$D$3:$D$4997,$X$2,COMPRAS!$B$3:$B$4997,">="&IF($C$4="",DATE(1900,1,1),$C$4),COMPRAS!$B$3:$B$4997,"<="&IF($F$4="",DATE(2999,12,31),$F$4)),0)) -> 0 | Z8: =IF($X$2="TODOS",V8,IF(S8<>"",SUMIFS(COMPRAS!$O$3:$O$4997,COMPRAS!$G$3:$G$4997,S8,COMPRAS!$D$3:$D$4997,$X$2,COMPRAS!$B$3:$B$4997,">="&IF($C$4="",DATE(1900,1,1),$C$4),COMPRAS!$B$3:$B$4997,"<="&IF($F$4="",DATE(2999,12,31),$F$4)),0)) -> 0
A9: 3 | B9: =IFERROR(INDEX($O$2:$O$206,MATCH(LARGE($P$2:$P$206,3),$P$2:$P$206,0)),"") -> COPESA | C9: =IFERROR(LARGE($P$2:$P$206,3),0) -> 18026.85 | E9: 3 | F9: =IFERROR(INDEX($O$2:$O$206,MATCH(LARGE($Q$2:$Q$206,3),$Q$2:$Q$206,0)),"") -> SUBASTAS RIVERA S.L. | G9: =IFERROR(LARGE($Q$2:$Q$206,3),0) -> 43626.4 | N9: =PROVEEDORES!A10 -> 50056 | O9: =PROVEEDORES!B10 -> COTON Y SANCHEZ S.L. | P9: =IF(N9<>"",SUMIFS(COMPRAS!$J$3:$J$4997,COMPRAS!$D$3:$D$4997,N9,COMPRAS!$B$3:$B$4997,">="&IF($C$4="",DATE(1900,1,1),$C$4),COMPRAS!$B$3:$B$4997,"<="&IF($F$4="",DATE(2999,12,31),$F$4)),0) -> 36 | Q9: =IF(N9<>"",SUMIFS(COMPRAS!$O$3:$O$4997,COMPRAS!$D$3:$D$4997,N9,COMPRAS!$B$3:$B$4997,">="&IF($C$4="",DATE(1900,1,1),$C$4),COMPRAS!$B$3:$B$4997,"<="&IF($F$4="",DATE(2999,12,31),$F$4)),0) -> 100.8 | S9: =PRODUCTOS!A10 -> 0 | T9: =PRODUCTOS!B10 -> 0 | U9: =IF(S9<>"",SUMIFS(COMPRAS!$J$3:$J$4997,COMPRAS!$G$3:$G$4997,S9,COMPRAS!$B$3:$B$4997,">="&IF($C$4="",DATE(1900,1,1),$C$4),COMPRAS!$B$3:$B$4997,"<="&IF($F$4="",DATE(2999,12,31),$F$4)),0) -> 0 | V9: =IF(S9<>"",SUMIFS(COMPRAS!$O$3:$O$4997,COMPRAS!$G$3:$G$4997,S9,COMPRAS!$B$3:$B$4997,">="&IF($C$4="",DATE(1900,1,1),$C$4),COMPRAS!$B$3:$B$4997,"<="&IF($F$4="",DATE(2999,12,31),$F$4)),0) -> 0 | Y9: =IF($X$2="TODOS",U9,IF(S9<>"",SUMIFS(COMPRAS!$J$3:$J$4997,COMPRAS!$G$3:$G$4997,S9,COMPRAS!$D$3:$D$4997,$X$2,COMPRAS!$B$3:$B$4997,">="&IF($C$4="",DATE(1900,1,1),$C$4),COMPRAS!$B$3:$B$4997,"<="&IF($F$4="",DATE(2999,12,31),$F$4)),0)) -> 0 | Z9: =IF($X$2="TODOS",V9,IF(S9<>"",SUMIFS(COMPRAS!$O$3:$O$4997,COMPRAS!$G$3:$G$4997,S9,COMPRAS!$D$3:$D$4997,$X$2,COMPRAS!$B$3:$B$4997,">="&IF($C$4="",DATE(1900,1,1),$C$4),COMPRAS!$B$3:$B$4997,"<="&IF($F$4="",DATE(2999,12,31),$F$4)),0)) -> 0
A10: 4 | B10: =IFERROR(INDEX($O$2:$O$206,MATCH(LARGE($P$2:$P$206,4),$P$2:$P$206,0)),"") -> JOSE LUIS CORREA KESSLER S.L. | C10: =IFERROR(LARGE($P$2:$P$206,4),0) -> 15321 | E10: 4 | F10: =IFERROR(INDEX($O$2:$O$206,MATCH(LARGE($Q$2:$Q$206,4),$Q$2:$Q$206,0)),"") -> SCANFISK SEAFFOD S,L | G10: =IFERROR(LARGE($Q$2:$Q$206,4),0) -> 35388.74 | N10: =PROVEEDORES!A11 -> 50064 | O10: =PROVEEDORES!B11 -> PESCADOS CORCUBION | P10: =IF(N10<>"",SUMIFS(COMPRAS!$J$3:$J$4997,COMPRAS!$D$3:$D$4997,N10,COMPRAS!$B$3:$B$4997,">="&IF($C$4="",DATE(1900,1,1),$C$4),COMPRAS!$B$3:$B$4997,"<="&IF($F$4="",DATE(2999,12,31),$F$4)),0) -> 0 | Q10: =IF(N10<>"",SUMIFS(COMPRAS!$O$3:$O$4997,COMPRAS!$D$3:$D$4997,N10,COMPRAS!$B$3:$B$4997,">="&IF($C$4="",DATE(1900,1,1),$C$4),COMPRAS!$B$3:$B$4997,"<="&IF($F$4="",DATE(2999,12,31),$F$4)),0) -> 0 | S10: =PRODUCTOS!A11 -> 0 | T10: =PRODUCTOS!B11 -> 0 | U10: =IF(S10<>"",SUMIFS(COMPRAS!$J$3:$J$4997,COMPRAS!$G$3:$G$4997,S10,COMPRAS!$B$3:$B$4997,">="&IF($C$4="",DATE(1900,1,1),$C$4),COMPRAS!$B$3:$B$4997,"<="&IF($F$4="",DATE(2999,12,31),$F$4)),0) -> 0 | V10: =IF(S10<>"",SUMIFS(COMPRAS!$O$3:$O$4997,COMPRAS!$G$3:$G$4997,S10,COMPRAS!$B$3:$B$4997,">="&IF($C$4="",DATE(1900,1,1),$C$4),COMPRAS!$B$3:$B$4997,"<="&IF($F$4="",DATE(2999,12,31),$F$4)),0) -> 0 | Y10: =IF($X$2="TODOS",U10,IF(S10<>"",SUMIFS(COMPRAS!$J$3:$J$4997,COMPRAS!$G$3:$G$4997,S10,COMPRAS!$D$3:$D$4997,$X$2,COMPRAS!$B$3:$B$4997,">="&IF($C$4="",DATE(1900,1,1),$C$4),COMPRAS!$B$3:$B$4997,"<="&IF($F$4="",DATE(2999,12,31),$F$4)),0)) -> 0 | Z10: =IF($X$2="TODOS",V10,IF(S10<>"",SUMIFS(COMPRAS!$O$3:$O$4997,COMPRAS!$G$3:$G$4997,S10,COMPRAS!$D$3:$D$4997,$X$2,COMPRAS!$B$3:$B$4997,">="&IF($C$4="",DATE(1900,1,1),$C$4),COMPRAS!$B$3:$B$4997,"<="&IF($F$4="",DATE(2999,12,31),$F$4)),0)) -> 0
A11: 5 | B11: =IFERROR(INDEX($O$2:$O$206,MATCH(LARGE($P$2:$P$206,5),$P$2:$P$206,0)),"") -> ACERGA | C11: =IFERROR(LARGE($P$2:$P$206,5),0) -> 13166 | E11: 5 | F11: =IFERROR(INDEX($O$2:$O$206,MATCH(LARGE($Q$2:$Q$206,5),$Q$2:$Q$206,0)),"") -> SUBASTAS CORUÑA S.L. | G11: =IFERROR(LARGE($Q$2:$Q$206,5),0) -> 35085.682 | N11: =PROVEEDORES!A12 -> 50069 | O11: =PROVEEDORES!B12 -> PESCADOS ILLANES S.L. | P11: =IF(N11<>"",SUMIFS(COMPRAS!$J$3:$J$4997,COMPRAS!$D$3:$D$4997,N11,COMPRAS!$B$3:$B$4997,">="&IF($C$4="",DATE(1900,1,1),$C$4),COMPRAS!$B$3:$B$4997,"<="&IF($F$4="",DATE(2999,12,31),$F$4)),0) -> 1083.6 | Q11: =IF(N11<>"",SUMIFS(COMPRAS!$O$3:$O$4997,COMPRAS!$D$3:$D$4997,N11,COMPRAS!$B$3:$B$4997,">="&IF($C$4="",DATE(1900,1,1),$C$4),COMPRAS!$B$3:$B$4997,"<="&IF($F$4="",DATE(2999,12,31),$F$4)),0) -> 4802.8434 | S11: =PRODUCTOS!A12 -> C650 | T11: =PRODUCTOS!B12 -> ABADEJO RIA (POL) | U11: =IF(S11<>"",SUMIFS(COMPRAS!$J$3:$J$4997,COMPRAS!$G$3:$G$4997,S11,COMPRAS!$B$3:$B$4997,">="&IF($C$4="",DATE(1900,1,1),$C$4),COMPRAS!$B$3:$B$4997,"<="&IF($F$4="",DATE(2999,12,31),$F$4)),0) -> 0 | V11: =IF(S11<>"",SUMIFS(COMPRAS!$O$3:$O$4997,COMPRAS!$G$3:$G$4997,S11,COMPRAS!$B$3:$B$4997,">="&IF($C$4="",DATE(1900,1,1),$C$4),COMPRAS!$B$3:$B$4997,"<="&IF($F$4="",DATE(2999,12,31),$F$4)),0) -> 0 | Y11: =IF($X$2="TODOS",U11,IF(S11<>"",SUMIFS(COMPRAS!$J$3:$J$4997,COMPRAS!$G$3:$G$4997,S11,COMPRAS!$D$3:$D$4997,$X$2,COMPRAS!$B$3:$B$4997,">="&IF($C$4="",DATE(1900,1,1),$C$4),COMPRAS!$B$3:$B$4997,"<="&IF($F$4="",DATE(2999,12,31),$F$4)),0)) -> 0 | Z11: =IF($X$2="TODOS",V11,IF(S11<>"",SUMIFS(COMPRAS!$O$3:$O$4997,COMPRAS!$G$3:$G$4997,S11,COMPRAS!$D$3:$D$4997,$X$2,COMPRAS!$B$3:$B$4997,">="&IF($C$4="",DATE(1900,1,1),$C$4),COMPRAS!$B$3:$B$4997,"<="&IF($F$4="",DATE(2999,12,31),$F$4)),0)) -> 0
A12: 6 | B12: =IFERROR(INDEX($O$2:$O$206,MATCH(LARGE($P$2:$P$206,6),$P$2:$P$206,0)),"") -> SUBASTAS DE ATLANTICO S.L | C12: =IFERROR(LARGE($P$2:$P$206,6),0) -> 9861.3 | E12: 6 | F12: =IFERROR(INDEX($O$2:$O$206,MATCH(LARGE($Q$2:$Q$206,6),$Q$2:$Q$206,0)),"") -> JOSE LUIS CORREA KESSLER S.L. | G12: =IFERROR(LARGE($Q$2:$Q$206,6),0) -> 31840.2 | N12: =PROVEEDORES!A13 -> 50106 | O12: =PROVEEDORES!B13 -> SONIA VENTAS S.L | P12: =IF(N12<>"",SUMIFS(COMPRAS!$J$3:$J$4997,COMPRAS!$D$3:$D$4997,N12,COMPRAS!$B$3:$B$4997,">="&IF($C$4="",DATE(1900,1,1),$C$4),COMPRAS!$B$3:$B$4997,"<="&IF($F$4="",DATE(2999,12,31),$F$4)),0) -> 4675.7 | Q12: =IF(N12<>"",SUMIFS(COMPRAS!$O$3:$O$4997,COMPRAS!$D$3:$D$4997,N12,COMPRAS!$B$3:$B$4997,">="&IF($C$4="",DATE(1900,1,1),$C$4),COMPRAS!$B$3:$B$4997,"<="&IF($F$4="",DATE(2999,12,31),$F$4)),0) -> 29402.495 | S12: =PRODUCTOS!A13 -> C620 | T12: =PRODUCTOS!B13 -> ACEDIA (CET) | U12: =IF(S12<>"",SUMIFS(COMPRAS!$J$3:$J$4997,COMPRAS!$G$3:$G$4997,S12,COMPRAS!$B$3:$B$4997,">="&IF($C$4="",DATE(1900,1,1),$C$4),COMPRAS!$B$3:$B$4997,"<="&IF($F$4="",DATE(2999,12,31),$F$4)),0) -> 0 | V12: =IF(S12<>"",SUMIFS(COMPRAS!$O$3:$O$4997,COMPRAS!$G$3:$G$4997,S12,COMPRAS!$B$3:$B$4997,">="&IF($C$4="",DATE(1900,1,1),$C$4),COMPRAS!$B$3:$B$4997,"<="&IF($F$4="",DATE(2999,12,31),$F$4)),0) -> 0 | Y12: =IF($X$2="TODOS",U12,IF(S12<>"",SUMIFS(COMPRAS!$J$3:$J$4997,COMPRAS!$G$3:$G$4997,S12,COMPRAS!$D$3:$D$4997,$X$2,COMPRAS!$B$3:$B$4997,">="&IF($C$4="",DATE(1900,1,1),$C$4),COMPRAS!$B$3:$B$4997,"<="&IF($F$4="",DATE(2999,12,31),$F$4)),0)) -> 0 | Z12: =IF($X$2="TODOS",V12,IF(S12<>"",SUMIFS(COMPRAS!$O$3:$O$4997,COMPRAS!$G$3:$G$4997,S12,COMPRAS!$D$3:$D$4997,$X$2,COMPRAS!$B$3:$B$4997,">="&IF($C$4="",DATE(1900,1,1),$C$4),COMPRAS!$B$3:$B$4997,"<="&IF($F$4="",DATE(2999,12,31),$F$4)),0)) -> 0
A13: 7 | B13: =IFERROR(INDEX($O$2:$O$206,MATCH(LARGE($P$2:$P$206,7),$P$2:$P$206,0)),"") -> SUBASTAS RIVERA S.L. | C13: =IFERROR(LARGE($P$2:$P$206,7),0) -> 9601.75 | E13: 7 | F13: =IFERROR(INDEX($O$2:$O$206,MATCH(LARGE($Q$2:$Q$206,7),$Q$2:$Q$206,0)),"") -> SONIA VENTAS S.L | G13: =IFERROR(LARGE($Q$2:$Q$206,7),0) -> 29402.495 | N13: =PROVEEDORES!A14 -> 50146 | O13: =PROVEEDORES!B14 -> MAR BERMEO S.L. | P13: =IF(N13<>"",SUMIFS(COMPRAS!$J$3:$J$4997,COMPRAS!$D$3:$D$4997,N13,COMPRAS!$B$3:$B$4997,">="&IF($C$4="",DATE(1900,1,1),$C$4),COMPRAS!$B$3:$B$4997,"<="&IF($F$4="",DATE(2999,12,31),$F$4)),0) -> 803.65 | Q13: =IF(N13<>"",SUMIFS(COMPRAS!$O$3:$O$4997,COMPRAS!$D$3:$D$4997,N13,COMPRAS!$B$3:$B$4997,">="&IF($C$4="",DATE(1900,1,1),$C$4),COMPRAS!$B$3:$B$4997,"<="&IF($F$4="",DATE(2999,12,31),$F$4)),0) -> 1788.1212 | S13: =PRODUCTOS!A14 -> C2555 | T13: =PRODUCTOS!B14 -> ALFONDIGA/RUBIO/ESCACHO (GUU) | U13: =IF(S13<>"",SUMIFS(COMPRAS!$J$3:$J$4997,COMPRAS!$G$3:$G$4997,S13,COMPRAS!$B$3:$B$4997,">="&IF($C$4="",DATE(1900,1,1),$C$4),COMPRAS!$B$3:$B$4997,"<="&IF($F$4="",DATE(2999,12,31),$F$4)),0) -> 26.95 | V13: =IF(S13<>"",SUMIFS(COMPRAS!$O$3:$O$4997,COMPRAS!$G$3:$G$4997,S13,COMPRAS!$B$3:$B$4997,">="&IF($C$4="",DATE(1900,1,1),$C$4),COMPRAS!$B$3:$B$4997,"<="&IF($F$4="",DATE(2999,12,31),$F$4)),0) -> 40.6215 | Y13: =IF($X$2="TODOS",U13,IF(S13<>"",SUMIFS(COMPRAS!$J$3:$J$4997,COMPRAS!$G$3:$G$4997,S13,COMPRAS!$D$3:$D$4997,$X$2,COMPRAS!$B$3:$B$4997,">="&IF($C$4="",DATE(1900,1,1),$C$4),COMPRAS!$B$3:$B$4997,"<="&IF($F$4="",DATE(2999,12,31),$F$4)),0)) -> 26.95 | Z13: =IF($X$2="TODOS",V13,IF(S13<>"",SUMIFS(COMPRAS!$O$3:$O$4997,COMPRAS!$G$3:$G$4997,S13,COMPRAS!$D$3:$D$4997,$X$2,COMPRAS!$B$3:$B$4997,">="&IF($C$4="",DATE(1900,1,1),$C$4),COMPRAS!$B$3:$B$4997,"<="&IF($F$4="",DATE(2999,12,31),$F$4)),0)) -> 40.6215
A14: 8 | B14: =IFERROR(INDEX($O$2:$O$206,MATCH(LARGE($P$2:$P$206,8),$P$2:$P$206,0)),"") -> SCANFISK SEAFFOD S,L | C14: =IFERROR(LARGE($P$2:$P$206,8),0) -> 4941.7 | E14: 8 | F14: =IFERROR(INDEX($O$2:$O$206,MATCH(LARGE($Q$2:$Q$206,8),$Q$2:$Q$206,0)),"") -> SUBASTAS DE ATLANTICO S.L | G14: =IFERROR(LARGE($Q$2:$Q$206,8),0) -> 24987.662 | N14: =PROVEEDORES!A15 -> 50152 | O14: =PROVEEDORES!B15 -> DOMAR CORUÑA S.L | P14: =IF(N14<>"",SUMIFS(COMPRAS!$J$3:$J$4997,COMPRAS!$D$3:$D$4997,N14,COMPRAS!$B$3:$B$4997,">="&IF($C$4="",DATE(1900,1,1),$C$4),COMPRAS!$B$3:$B$4997,"<="&IF($F$4="",DATE(2999,12,31),$F$4)),0) -> 68 | Q14: =IF(N14<>"",SUMIFS(COMPRAS!$O$3:$O$4997,COMPRAS!$D$3:$D$4997,N14,COMPRAS!$B$3:$B$4997,">="&IF($C$4="",DATE(1900,1,1),$C$4),COMPRAS!$B$3:$B$4997,"<="&IF($F$4="",DATE(2999,12,31),$F$4)),0) -> 1200 | S14: =PRODUCTOS!A15 -> C3972 | T14: =PRODUCTOS!B15 -> ATUN PATUDO (BET) | U14: =IF(S14<>"",SUMIFS(COMPRAS!$J$3:$J$4997,COMPRAS!$G$3:$G$4997,S14,COMPRAS!$B$3:$B$4997,">="&IF($C$4="",DATE(1900,1,1),$C$4),COMPRAS!$B$3:$B$4997,"<="&IF($F$4="",DATE(2999,12,31),$F$4)),0) -> 0 | V14: =IF(S14<>"",SUMIFS(COMPRAS!$O$3:$O$4997,COMPRAS!$G$3:$G$4997,S14,COMPRAS!$B$3:$B$4997,">="&IF($C$4="",DATE(1900,1,1),$C$4),COMPRAS!$B$3:$B$4997,"<="&IF($F$4="",DATE(2999,12,31),$F$4)),0) -> 0 | Y14: =IF($X$2="TODOS",U14,IF(S14<>"",SUMIFS(COMPRAS!$J$3:$J$4997,COMPRAS!$G$3:$G$4997,S14,COMPRAS!$D$3:$D$4997,$X$2,COMPRAS!$B$3:$B$4997,">="&IF($C$4="",DATE(1900,1,1),$C$4),COMPRAS!$B$3:$B$4997,"<="&IF($F$4="",DATE(2999,12,31),$F$4)),0)) -> 0 | Z14: =IF($X$2="TODOS",V14,IF(S14<>"",SUMIFS(COMPRAS!$O$3:$O$4997,COMPRAS!$G$3:$G$4997,S14,COMPRAS!$D$3:$D$4997,$X$2,COMPRAS!$B$3:$B$4997,">="&IF($C$4="",DATE(1900,1,1),$C$4),COMPRAS!$B$3:$B$4997,"<="&IF($F$4="",DATE(2999,12,31),$F$4)),0)) -> 0
A15: 9 | B15: =IFERROR(INDEX($O$2:$O$206,MATCH(LARGE($P$2:$P$206,9),$P$2:$P$206,0)),"") -> SONIA VENTAS S.L | C15: =IFERROR(LARGE($P$2:$P$206,9),0) -> 4675.7 | E15: 9 | F15: =IFERROR(INDEX($O$2:$O$206,MATCH(LARGE($Q$2:$Q$206,9),$Q$2:$Q$206,0)),"") -> ACERGA | G15: =IFERROR(LARGE($Q$2:$Q$206,9),0) -> 20065.787 | N15: =PROVEEDORES!A16 -> 50158 | O15: =PROVEEDORES!B16 -> FORO-MAREE | P15: =IF(N15<>"",SUMIFS(COMPRAS!$J$3:$J$4997,COMPRAS!$D$3:$D$4997,N15,COMPRAS!$B$3:$B$4997,">="&IF($C$4="",DATE(1900,1,1),$C$4),COMPRAS!$B$3:$B$4997,"<="&IF($F$4="",DATE(2999,12,31),$F$4)),0) -> 0 | Q15: =IF(N15<>"",SUMIFS(COMPRAS!$O$3:$O$4997,COMPRAS!$D$3:$D$4997,N15,COMPRAS!$B$3:$B$4997,">="&IF($C$4="",DATE(1900,1,1),$C$4),COMPRAS!$B$3:$B$4997,"<="&IF($F$4="",DATE(2999,12,31),$F$4)),0) -> 0 | S15: =PRODUCTOS!A16 -> C8020 | T15: =PRODUCTOS!B16 -> FILETE DE BACALO (COD) | U15: =IF(S15<>"",SUMIFS(COMPRAS!$J$3:$J$4997,COMPRAS!$G$3:$G$4997,S15,COMPRAS!$B$3:$B$4997,">="&IF($C$4="",DATE(1900,1,1),$C$4),COMPRAS!$B$3:$B$4997,"<="&IF($F$4="",DATE(2999,12,31),$F$4)),0) -> 0 | V15: =IF(S15<>"",SUMIFS(COMPRAS!$O$3:$O$4997,COMPRAS!$G$3:$G$4997,S15,COMPRAS!$B$3:$B$4997,">="&IF($C$4="",DATE(1900,1,1),$C$4),COMPRAS!$B$3:$B$4997,"<="&IF($F$4="",DATE(2999,12,31),$F$4)),0) -> 0 | Y15: =IF($X$2="TODOS",U15,IF(S15<>"",SUMIFS(COMPRAS!$J$3:$J$4997,COMPRAS!$G$3:$G$4997,S15,COMPRAS!$D$3:$D$4997,$X$2,COMPRAS!$B$3:$B$4997,">="&IF($C$4="",DATE(1900,1,1),$C$4),COMPRAS!$B$3:$B$4997,"<="&IF($F$4="",DATE(2999,12,31),$F$4)),0)) -> 0 | Z15: =IF($X$2="TODOS",V15,IF(S15<>"",SUMIFS(COMPRAS!$O$3:$O$4997,COMPRAS!$G$3:$G$4997,S15,COMPRAS!$D$3:$D$4997,$X$2,COMPRAS!$B$3:$B$4997,">="&IF($C$4="",DATE(1900,1,1),$C$4),COMPRAS!$B$3:$B$4997,"<="&IF($F$4="",DATE(2999,12,31),$F$4)),0)) -> 0
A16: 10 | B16: =IFERROR(INDEX($O$2:$O$206,MATCH(LARGE($P$2:$P$206,10),$P$2:$P$206,0)),"") -> PERFECTO MONTERO | C16: =IFERROR(LARGE($P$2:$P$206,10),0) -> 2834.25 | E16: 10 | F16: =IFERROR(INDEX($O$2:$O$206,MATCH(LARGE($Q$2:$Q$206,10),$Q$2:$Q$206,0)),"") -> PERFECTO MONTERO | G16: =IFERROR(LARGE($Q$2:$Q$206,10),0) -> 15098.976 | N16: =PROVEEDORES!A17 -> 50160 | O16: =PROVEEDORES!B17 -> SUBASTAS CORUÑA S.L. | P16: =IF(N16<>"",SUMIFS(COMPRAS!$J$3:$J$4997,COMPRAS!$D$3:$D$4997,N16,COMPRAS!$B$3:$B$4997,">="&IF($C$4="",DATE(1900,1,1),$C$4),COMPRAS!$B$3:$B$4997,"<="&IF($F$4="",DATE(2999,12,31),$F$4)),0) -> 18832.8 | Q16: =IF(N16<>"",SUMIFS(COMPRAS!$O$3:$O$4997,COMPRAS!$D$3:$D$4997,N16,COMPRAS!$B$3:$B$4997,">="&IF($C$4="",DATE(1900,1,1),$C$4),COMPRAS!$B$3:$B$4997,"<="&IF($F$4="",DATE(2999,12,31),$F$4)),0) -> 35085.682 | S16: =PRODUCTOS!A17 -> C802 | T16: =PRODUCTOS!B17 -> BACALAO FRESCO (COD) | U16: =IF(S16<>"",SUMIFS(COMPRAS!$J$3:$J$4997,COMPRAS!$G$3:$G$4997,S16,COMPRAS!$B$3:$B$4997,">="&IF($C$4="",DATE(1900,1,1),$C$4),COMPRAS!$B$3:$B$4997,"<="&IF($F$4="",DATE(2999,12,31),$F$4)),0) -> 0 | V16: =IF(S16<>"",SUMIFS(COMPRAS!$O$3:$O$4997,COMPRAS!$G$3:$G$4997,S16,COMPRAS!$B$3:$B$4997,">="&IF($C$4="",DATE(1900,1,1),$C$4),COMPRAS!$B$3:$B$4997,"<="&IF($F$4="",DATE(2999,12,31),$F$4)),0) -> 0 | Y16: =IF($X$2="TODOS",U16,IF(S16<>"",SUMIFS(COMPRAS!$J$3:$J$4997,COMPRAS!$G$3:$G$4997,S16,COMPRAS!$D$3:$D$4997,$X$2,COMPRAS!$B$3:$B$4997,">="&IF($C$4="",DATE(1900,1,1),$C$4),COMPRAS!$B$3:$B$4997,"<="&IF($F$4="",DATE(2999,12,31),$F$4)),0)) -> 0 | Z16: =IF($X$2="TODOS",V16,IF(S16<>"",SUMIFS(COMPRAS!$O$3:$O$4997,COMPRAS!$G$3:$G$4997,S16,COMPRAS!$D$3:$D$4997,$X$2,COMPRAS!$B$3:$B$4997,">="&IF($C$4="",DATE(1900,1,1),$C$4),COMPRAS!$B$3:$B$4997,"<="&IF($F$4="",DATE(2999,12,31),$F$4)),0)) -> 0
A17: 11 | B17: =IFERROR(INDEX($O$2:$O$206,MATCH(LARGE($P$2:$P$206,11),$P$2:$P$206,0)),"") -> PACO MOINELO | C17: =IFERROR(LARGE($P$2:$P$206,11),0) -> 1761.55 | E17: 11 | F17: =IFERROR(INDEX($O$2:$O$206,MATCH(LARGE($Q$2:$Q$206,11),$Q$2:$Q$206,0)),"") -> AZORFISK UNIPERSONAL LDA | G17: =IFERROR(LARGE($Q$2:$Q$206,11),0) -> 14685.925 | N17: =PROVEEDORES!A18 -> 50163 | O17: =PROVEEDORES!B18 -> SUBASTAS RIVERA S.L. | P17: =IF(N17<>"",SUMIFS(COMPRAS!$J$3:$J$4997,COMPRAS!$D$3:$D$4997,N17,COMPRAS!$B$3:$B$4997,">="&IF($C$4="",DATE(1900,1,1),$C$4),COMPRAS!$B$3:$B$4997,"<="&IF($F$4="",DATE(2999,12,31),$F$4)),0) -> 9601.75 | Q17: =IF(N17<>"",SUMIFS(COMPRAS!$O$3:$O$4997,COMPRAS!$D$3:$D$4997,N17,COMPRAS!$B$3:$B$4997,">="&IF($C$4="",DATE(1900,1,1),$C$4),COMPRAS!$B$3:$B$4997,"<="&IF($F$4="",DATE(2999,12,31),$F$4)),0) -> 43626.4 | S17: =PRODUCTOS!A18 -> C8021 | T17: =PRODUCTOS!B18 -> COCOCHAS DE BACALAO (COD) | U17: =IF(S17<>"",SUMIFS(COMPRAS!$J$3:$J$4997,COMPRAS!$G$3:$G$4997,S17,COMPRAS!$B$3:$B$4997,">="&IF($C$4="",DATE(1900,1,1),$C$4),COMPRAS!$B$3:$B$4997,"<="&IF($F$4="",DATE(2999,12,31),$F$4)),0) -> 0 | V17: =IF(S17<>"",SUMIFS(COMPRAS!$O$3:$O$4997,COMPRAS!$G$3:$G$4997,S17,COMPRAS!$B$3:$B$4997,">="&IF($C$4="",DATE(1900,1,1),$C$4),COMPRAS!$B$3:$B$4997,"<="&IF($F$4="",DATE(2999,12,31),$F$4)),0) -> 0 | Y17: =IF($X$2="TODOS",U17,IF(S17<>"",SUMIFS(COMPRAS!$J$3:$J$4997,COMPRAS!$G$3:$G$4997,S17,COMPRAS!$D$3:$D$4997,$X$2,COMPRAS!$B$3:$B$4997,">="&IF($C$4="",DATE(1900,1,1),$C$4),COMPRAS!$B$3:$B$4997,"<="&IF($F$4="",DATE(2999,12,31),$F$4)),0)) -> 0 | Z17: =IF($X$2="TODOS",V17,IF(S17<>"",SUMIFS(COMPRAS!$O$3:$O$4997,COMPRAS!$G$3:$G$4997,S17,COMPRAS!$D$3:$D$4997,$X$2,COMPRAS!$B$3:$B$4997,">="&IF($C$4="",DATE(1900,1,1),$C$4),COMPRAS!$B$3:$B$4997,"<="&IF($F$4="",DATE(2999,12,31),$F$4)),0)) -> 0
A18: 12 | B18: =IFERROR(INDEX($O$2:$O$206,MATCH(LARGE($P$2:$P$206,12),$P$2:$P$206,0)),"") -> LURDES MARIÑO, S.L. | C18: =IFERROR(LARGE($P$2:$P$206,12),0) -> 1215 | E18: 12 | F18: =IFERROR(INDEX($O$2:$O$206,MATCH(LARGE($Q$2:$Q$206,12),$Q$2:$Q$206,0)),"") -> FURIC MAREE | G18: =IFERROR(LARGE($Q$2:$Q$206,12),0) -> 14000.16 | N18: =PROVEEDORES!A19 -> 50164 | O18: =PROVEEDORES!B19 -> ABRGO NORTE S.L. | P18: =IF(N18<>"",SUMIFS(COMPRAS!$J$3:$J$4997,COMPRAS!$D$3:$D$4997,N18,COMPRAS!$B$3:$B$4997,">="&IF($C$4="",DATE(1900,1,1),$C$4),COMPRAS!$B$3:$B$4997,"<="&IF($F$4="",DATE(2999,12,31),$F$4)),0) -> 240 | Q18: =IF(N18<>"",SUMIFS(COMPRAS!$O$3:$O$4997,COMPRAS!$D$3:$D$4997,N18,COMPRAS!$B$3:$B$4997,">="&IF($C$4="",DATE(1900,1,1),$C$4),COMPRAS!$B$3:$B$4997,"<="&IF($F$4="",DATE(2999,12,31),$F$4)),0) -> 2027.5 | S18: =PRODUCTOS!A19 -> C1546 | T18: =PRODUCTOS!B19 -> BERTORELLA ROCA (FOR) | U18: =IF(S18<>"",SUMIFS(COMPRAS!$J$3:$J$4997,COMPRAS!$G$3:$G$4997,S18,COMPRAS!$B$3:$B$4997,">="&IF($C$4="",DATE(1900,1,1),$C$4),COMPRAS!$B$3:$B$4997,"<="&IF($F$4="",DATE(2999,12,31),$F$4)),0) -> 444.75 | V18: =IF(S18<>"",SUMIFS(COMPRAS!$O$3:$O$4997,COMPRAS!$G$3:$G$4997,S18,COMPRAS!$B$3:$B$4997,">="&IF($C$4="",DATE(1900,1,1),$C$4),COMPRAS!$B$3:$B$4997,"<="&IF($F$4="",DATE(2999,12,31),$F$4)),0) -> 1315.29 | Y18: =IF($X$2="TODOS",U18,IF(S18<>"",SUMIFS(COMPRAS!$J$3:$J$4997,COMPRAS!$G$3:$G$4997,S18,COMPRAS!$D$3:$D$4997,$X$2,COMPRAS!$B$3:$B$4997,">="&IF($C$4="",DATE(1900,1,1),$C$4),COMPRAS!$B$3:$B$4997,"<="&IF($F$4="",DATE(2999,12,31),$F$4)),0)) -> 444.75 | Z18: =IF($X$2="TODOS",V18,IF(S18<>"",SUMIFS(COMPRAS!$O$3:$O$4997,COMPRAS!$G$3:$G$4997,S18,COMPRAS!$D$3:$D$4997,$X$2,COMPRAS!$B$3:$B$4997,">="&IF($C$4="",DATE(1900,1,1),$C$4),COMPRAS!$B$3:$B$4997,"<="&IF($F$4="",DATE(2999,12,31),$F$4)),0)) -> 1315.29
A19: 13 | B19: =IFERROR(INDEX($O$2:$O$206,MATCH(LARGE($P$2:$P$206,13),$P$2:$P$206,0)),"") -> PESCADOS ILLANES S.L. | C19: =IFERROR(LARGE($P$2:$P$206,13),0) -> 1083.6 | E19: 13 | F19: =IFERROR(INDEX($O$2:$O$206,MATCH(LARGE($Q$2:$Q$206,13),$Q$2:$Q$206,0)),"") -> PACO MOINELO | G19: =IFERROR(LARGE($Q$2:$Q$206,13),0) -> 10973.989 | N19: =PROVEEDORES!A20 -> 50190 | O19: =PROVEEDORES!B20 -> PEIXES E MARISCOS ANEIROS S.L. | P19: =IF(N19<>"",SUMIFS(COMPRAS!$J$3:$J$4997,COMPRAS!$D$3:$D$4997,N19,COMPRAS!$B$3:$B$4997,">="&IF($C$4="",DATE(1900,1,1),$C$4),COMPRAS!$B$3:$B$4997,"<="&IF($F$4="",DATE(2999,12,31),$F$4)),0) -> 0 | Q19: =IF(N19<>"",SUMIFS(COMPRAS!$O$3:$O$4997,COMPRAS!$D$3:$D$4997,N19,COMPRAS!$B$3:$B$4997,">="&IF($C$4="",DATE(1900,1,1),$C$4),COMPRAS!$B$3:$B$4997,"<="&IF($F$4="",DATE(2999,12,31),$F$4)),0) -> 0 | S19: =PRODUCTOS!A20 -> C1545 | T19: =PRODUCTOS!B20 -> BERTORELLA (GFB) | U19: =IF(S19<>"",SUMIFS(COMPRAS!$J$3:$J$4997,COMPRAS!$G$3:$G$4997,S19,COMPRAS!$B$3:$B$4997,">="&IF($C$4="",DATE(1900,1,1),$C$4),COMPRAS!$B$3:$B$4997,"<="&IF($F$4="",DATE(2999,12,31),$F$4)),0) -> 1068.5 | V19: =IF(S19<>"",SUMIFS(COMPRAS!$O$3:$O$4997,COMPRAS!$G$3:$G$4997,S19,COMPRAS!$B$3:$B$4997,">="&IF($C$4="",DATE(1900,1,1),$C$4),COMPRAS!$B$3:$B$4997,"<="&IF($F$4="",DATE(2999,12,31),$F$4)),0) -> 3366.663 | Y19: =IF($X$2="TODOS",U19,IF(S19<>"",SUMIFS(COMPRAS!$J$3:$J$4997,COMPRAS!$G$3:$G$4997,S19,COMPRAS!$D$3:$D$4997,$X$2,COMPRAS!$B$3:$B$4997,">="&IF($C$4="",DATE(1900,1,1),$C$4),COMPRAS!$B$3:$B$4997,"<="&IF($F$4="",DATE(2999,12,31),$F$4)),0)) -> 1068.5 | Z19: =IF($X$2="TODOS",V19,IF(S19<>"",SUMIFS(COMPRAS!$O$3:$O$4997,COMPRAS!$G$3:$G$4997,S19,COMPRAS!$D$3:$D$4997,$X$2,COMPRAS!$B$3:$B$4997,">="&IF($C$4="",DATE(1900,1,1),$C$4),COMPRAS!$B$3:$B$4997,"<="&IF($F$4="",DATE(2999,12,31),$F$4)),0)) -> 3366.663
A20: 14 | B20: =IFERROR(INDEX($O$2:$O$206,MATCH(LARGE($P$2:$P$206,14),$P$2:$P$206,0)),"") -> ANGELPESCA S.L. | C20: =IFERROR(LARGE($P$2:$P$206,14),0) -> 1030 | E20: 14 | F20: =IFERROR(INDEX($O$2:$O$206,MATCH(LARGE($Q$2:$Q$206,14),$Q$2:$Q$206,0)),"") -> PESCADO Y MARISCOS ADELAIDA S.L. | G20: =IFERROR(LARGE($Q$2:$Q$206,14),0) -> 5474.4725 | N20: =PROVEEDORES!A21 -> 50196 | O20: =PROVEEDORES!B21 -> PORTABALES S.L. | P20: =IF(N20<>"",SUMIFS(COMPRAS!$J$3:$J$4997,COMPRAS!$D$3:$D$4997,N20,COMPRAS!$B$3:$B$4997,">="&IF($C$4="",DATE(1900,1,1),$C$4),COMPRAS!$B$3:$B$4997,"<="&IF($F$4="",DATE(2999,12,31),$F$4)),0) -> 10 | Q20: =IF(N20<>"",SUMIFS(COMPRAS!$O$3:$O$4997,COMPRAS!$D$3:$D$4997,N20,COMPRAS!$B$3:$B$4997,">="&IF($C$4="",DATE(1900,1,1),$C$4),COMPRAS!$B$3:$B$4997,"<="&IF($F$4="",DATE(2999,12,31),$F$4)),0) -> 30 | S20: =PRODUCTOS!A21 -> C365 | T20: =PRODUCTOS!B21 -> BESUGO (BSR) | U20: =IF(S20<>"",SUMIFS(COMPRAS!$J$3:$J$4997,COMPRAS!$G$3:$G$4997,S20,COMPRAS!$B$3:$B$4997,">="&IF($C$4="",DATE(1900,1,1),$C$4),COMPRAS!$B$3:$B$4997,"<="&IF($F$4="",DATE(2999,12,31),$F$4)),0) -> 358.1 | V20: =IF(S20<>"",SUMIFS(COMPRAS!$O$3:$O$4997,COMPRAS!$G$3:$G$4997,S20,COMPRAS!$B$3:$B$4997,">="&IF($C$4="",DATE(1900,1,1),$C$4),COMPRAS!$B$3:$B$4997,"<="&IF($F$4="",DATE(2999,12,31),$F$4)),0) -> 11163.798 | Y20: =IF($X$2="TODOS",U20,IF(S20<>"",SUMIFS(COMPRAS!$J$3:$J$4997,COMPRAS!$G$3:$G$4997,S20,COMPRAS!$D$3:$D$4997,$X$2,COMPRAS!$B$3:$B$4997,">="&IF($C$4="",DATE(1900,1,1),$C$4),COMPRAS!$B$3:$B$4997,"<="&IF($F$4="",DATE(2999,12,31),$F$4)),0)) -> 358.1 | Z20: =IF($X$2="TODOS",V20,IF(S20<>"",SUMIFS(COMPRAS!$O$3:$O$4997,COMPRAS!$G$3:$G$4997,S20,COMPRAS!$D$3:$D$4997,$X$2,COMPRAS!$B$3:$B$4997,">="&IF($C$4="",DATE(1900,1,1),$C$4),COMPRAS!$B$3:$B$4997,"<="&IF($F$4="",DATE(2999,12,31),$F$4)),0)) -> 11163.798
A21: 15 | B21: =IFERROR(INDEX($O$2:$O$206,MATCH(LARGE($P$2:$P$206,15),$P$2:$P$206,0)),"") -> PESCADO Y MARISCOS ADELAIDA S.L. | C21: =IFERROR(LARGE($P$2:$P$206,15),0) -> 937.74 | E21: 15 | F21: =IFERROR(INDEX($O$2:$O$206,MATCH(LARGE($Q$2:$Q$206,15),$Q$2:$Q$206,0)),"") -> PESCADOS ILLANES S.L. | G21: =IFERROR(LARGE($Q$2:$Q$206,15),0) -> 4802.8434 | N21: =PROVEEDORES!A22 -> 50201 | O21: =PROVEEDORES!B22 -> PESCADOS MANUELA GARCIA S.L | P21: =IF(N21<>"",SUMIFS(COMPRAS!$J$3:$J$4997,COMPRAS!$D$3:$D$4997,N21,COMPRAS!$B$3:$B$4997,">="&IF($C$4="",DATE(1900,1,1),$C$4),COMPRAS!$B$3:$B$4997,"<="&IF($F$4="",DATE(2999,12,31),$F$4)),0) -> 0 | Q21: =IF(N21<>"",SUMIFS(COMPRAS!$O$3:$O$4997,COMPRAS!$D$3:$D$4997,N21,COMPRAS!$B$3:$B$4997,">="&IF($C$4="",DATE(1900,1,1),$C$4),COMPRAS!$B$3:$B$4997,"<="&IF($F$4="",DATE(2999,12,31),$F$4)),0) -> 0 | S21: =PRODUCTOS!A22 -> C562 | T21: =PRODUCTOS!B22 -> BICUDO/ALIGOTE (SBA) | U21: =IF(S21<>"",SUMIFS(COMPRAS!$J$3:$J$4997,COMPRAS!$G$3:$G$4997,S21,COMPRAS!$B$3:$B$4997,">="&IF($C$4="",DATE(1900,1,1),$C$4),COMPRAS!$B$3:$B$4997,"<="&IF($F$4="",DATE(2999,12,31),$F$4)),0) -> 64.85 | V21: =IF(S21<>"",SUMIFS(COMPRAS!$O$3:$O$4997,COMPRAS!$G$3:$G$4997,S21,COMPRAS!$B$3:$B$4997,">="&IF($C$4="",DATE(1900,1,1),$C$4),COMPRAS!$B$3:$B$4997,"<="&IF($F$4="",DATE(2999,12,31),$F$4)),0) -> 398.1621 | Y21: =IF($X$2="TODOS",U21,IF(S21<>"",SUMIFS(COMPRAS!$J$3:$J$4997,COMPRAS!$G$3:$G$4997,S21,COMPRAS!$D$3:$D$4997,$X$2,COMPRAS!$B$3:$B$4997,">="&IF($C$4="",DATE(1900,1,1),$C$4),COMPRAS!$B$3:$B$4997,"<="&IF($F$4="",DATE(2999,12,31),$F$4)),0)) -> 64.85 | Z21: =IF($X$2="TODOS",V21,IF(S21<>"",SUMIFS(COMPRAS!$O$3:$O$4997,COMPRAS!$G$3:$G$4997,S21,COMPRAS!$D$3:$D$4997,$X$2,COMPRAS!$B$3:$B$4997,">="&IF($C$4="",DATE(1900,1,1),$C$4),COMPRAS!$B$3:$B$4997,"<="&IF($F$4="",DATE(2999,12,31),$F$4)),0)) -> 398.1621
N22: =PROVEEDORES!A23 -> 50207 | O22: =PROVEEDORES!B23 -> MARLEDICIA S.L | P22: =IF(N22<>"",SUMIFS(COMPRAS!$J$3:$J$4997,COMPRAS!$D$3:$D$4997,N22,COMPRAS!$B$3:$B$4997,">="&IF($C$4="",DATE(1900,1,1),$C$4),COMPRAS!$B$3:$B$4997,"<="&IF($F$4="",DATE(2999,12,31),$F$4)),0) -> 11.5 | Q22: =IF(N22<>"",SUMIFS(COMPRAS!$O$3:$O$4997,COMPRAS!$D$3:$D$4997,N22,COMPRAS!$B$3:$B$4997,">="&IF($C$4="",DATE(1900,1,1),$C$4),COMPRAS!$B$3:$B$4997,"<="&IF($F$4="",DATE(2999,12,31),$F$4)),0) -> 39.882 | S22: =PRODUCTOS!A23 -> C601 | T22: =PRODUCTOS!B23 -> BOGAVANTE CANADIENSE CHIX (LBA) | U22: =IF(S22<>"",SUMIFS(COMPRAS!$J$3:$J$4997,COMPRAS!$G$3:$G$4997,S22,COMPRAS!$B$3:$B$4997,">="&IF($C$4="",DATE(1900,1,1),$C$4),COMPRAS!$B$3:$B$4997,"<="&IF($F$4="",DATE(2999,12,31),$F$4)),0) -> 0 | V22: =IF(S22<>"",SUMIFS(COMPRAS!$O$3:$O$4997,COMPRAS!$G$3:$G$4997,S22,COMPRAS!$B$3:$B$4997,">="&IF($C$4="",DATE(1900,1,1),$C$4),COMPRAS!$B$3:$B$4997,"<="&IF($F$4="",DATE(2999,12,31),$F$4)),0) -> 0 | Y22: =IF($X$2="TODOS",U22,IF(S22<>"",SUMIFS(COMPRAS!$J$3:$J$4997,COMPRAS!$G$3:$G$4997,S22,COMPRAS!$D$3:$D$4997,$X$2,COMPRAS!$B$3:$B$4997,">="&IF($C$4="",DATE(1900,1,1),$C$4),COMPRAS!$B$3:$B$4997,"<="&IF($F$4="",DATE(2999,12,31),$F$4)),0)) -> 0 | Z22: =IF($X$2="TODOS",V22,IF(S22<>"",SUMIFS(COMPRAS!$O$3:$O$4997,COMPRAS!$G$3:$G$4997,S22,COMPRAS!$D$3:$D$4997,$X$2,COMPRAS!$B$3:$B$4997,">="&IF($C$4="",DATE(1900,1,1),$C$4),COMPRAS!$B$3:$B$4997,"<="&IF($F$4="",DATE(2999,12,31),$F$4)),0)) -> 0
N23: =PROVEEDORES!A24 -> 50213 | O23: =PROVEEDORES!B24 -> PESCADOS OCEANO ATLANTICO S.L. | P23: =IF(N23<>"",SUMIFS(COMPRAS!$J$3:$J$4997,COMPRAS!$D$3:$D$4997,N23,COMPRAS!$B$3:$B$4997,">="&IF($C$4="",DATE(1900,1,1),$C$4),COMPRAS!$B$3:$B$4997,"<="&IF($F$4="",DATE(2999,12,31),$F$4)),0) -> 36 | Q23: =IF(N23<>"",SUMIFS(COMPRAS!$O$3:$O$4997,COMPRAS!$D$3:$D$4997,N23,COMPRAS!$B$3:$B$4997,">="&IF($C$4="",DATE(1900,1,1),$C$4),COMPRAS!$B$3:$B$4997,"<="&IF($F$4="",DATE(2999,12,31),$F$4)),0) -> 108 | S23: =PRODUCTOS!A24 -> C3979 | T23: =PRODUCTOS!B24 -> BONITO DEL NORTE 5/7 | U23: =IF(S23<>"",SUMIFS(COMPRAS!$J$3:$J$4997,COMPRAS!$G$3:$G$4997,S23,COMPRAS!$B$3:$B$4997,">="&IF($C$4="",DATE(1900,1,1),$C$4),COMPRAS!$B$3:$B$4997,"<="&IF($F$4="",DATE(2999,12,31),$F$4)),0) -> 898.25 | V23: =IF(S23<>"",SUMIFS(COMPRAS!$O$3:$O$4997,COMPRAS!$G$3:$G$4997,S23,COMPRAS!$B$3:$B$4997,">="&IF($C$4="",DATE(1900,1,1),$C$4),COMPRAS!$B$3:$B$4997,"<="&IF($F$4="",DATE(2999,12,31),$F$4)),0) -> 3933.4642 | Y23: =IF($X$2="TODOS",U23,IF(S23<>"",SUMIFS(COMPRAS!$J$3:$J$4997,COMPRAS!$G$3:$G$4997,S23,COMPRAS!$D$3:$D$4997,$X$2,COMPRAS!$B$3:$B$4997,">="&IF($C$4="",DATE(1900,1,1),$C$4),COMPRAS!$B$3:$B$4997,"<="&IF($F$4="",DATE(2999,12,31),$F$4)),0)) -> 898.25 | Z23: =IF($X$2="TODOS",V23,IF(S23<>"",SUMIFS(COMPRAS!$O$3:$O$4997,COMPRAS!$G$3:$G$4997,S23,COMPRAS!$D$3:$D$4997,$X$2,COMPRAS!$B$3:$B$4997,">="&IF($C$4="",DATE(1900,1,1),$C$4),COMPRAS!$B$3:$B$4997,"<="&IF($F$4="",DATE(2999,12,31),$F$4)),0)) -> 3933.4642
A24: TOP 15 PRODUCTOS -- MAS KILOS COMPRADOS | E24: TOP 15 PRODUCTOS -- MAS IMPORTE COMPRADO | N24: =PROVEEDORES!A25 -> 50218 | O24: =PROVEEDORES!B25 -> ACERGA | P24: =IF(N24<>"",SUMIFS(COMPRAS!$J$3:$J$4997,COMPRAS!$D$3:$D$4997,N24,COMPRAS!$B$3:$B$4997,">="&IF($C$4="",DATE(1900,1,1),$C$4),COMPRAS!$B$3:$B$4997,"<="&IF($F$4="",DATE(2999,12,31),$F$4)),0) -> 13166 | Q24: =IF(N24<>"",SUMIFS(COMPRAS!$O$3:$O$4997,COMPRAS!$D$3:$D$4997,N24,COMPRAS!$B$3:$B$4997,">="&IF($C$4="",DATE(1900,1,1),$C$4),COMPRAS!$B$3:$B$4997,"<="&IF($F$4="",DATE(2999,12,31),$F$4)),0) -> 20065.787 | S24: =PRODUCTOS!A25 -> C397 | T24: =PRODUCTOS!B25 -> BONITO DEL NORTE 5/7 | U24: =IF(S24<>"",SUMIFS(COMPRAS!$J$3:$J$4997,COMPRAS!$G$3:$G$4997,S24,COMPRAS!$B$3:$B$4997,">="&IF($C$4="",DATE(1900,1,1),$C$4),COMPRAS!$B$3:$B$4997,"<="&IF($F$4="",DATE(2999,12,31),$F$4)),0) -> 3944.05 | V24: =IF(S24<>"",SUMIFS(COMPRAS!$O$3:$O$4997,COMPRAS!$G$3:$G$4997,S24,COMPRAS!$B$3:$B$4997,">="&IF($C$4="",DATE(1900,1,1),$C$4),COMPRAS!$B$3:$B$4997,"<="&IF($F$4="",DATE(2999,12,31),$F$4)),0) -> 19023.43 | Y24: =IF($X$2="TODOS",U24,IF(S24<>"",SUMIFS(COMPRAS!$J$3:$J$4997,COMPRAS!$G$3:$G$4997,S24,COMPRAS!$D$3:$D$4997,$X$2,COMPRAS!$B$3:$B$4997,">="&IF($C$4="",DATE(1900,1,1),$C$4),COMPRAS!$B$3:$B$4997,"<="&IF($F$4="",DATE(2999,12,31),$F$4)),0)) -> 3944.05 | Z24: =IF($X$2="TODOS",V24,IF(S24<>"",SUMIFS(COMPRAS!$O$3:$O$4997,COMPRAS!$G$3:$G$4997,S24,COMPRAS!$D$3:$D$4997,$X$2,COMPRAS!$B$3:$B$4997,">="&IF($C$4="",DATE(1900,1,1),$C$4),COMPRAS!$B$3:$B$4997,"<="&IF($F$4="",DATE(2999,12,31),$F$4)),0)) -> 19023.43
A25: # | B25: Producto | C25: Kilos | E25: # | F25: Producto | G25: Importe | N25: =PROVEEDORES!A26 -> 50227 | O25: =PROVEEDORES!B26 -> BRISAMAR | P25: =IF(N25<>"",SUMIFS(COMPRAS!$J$3:$J$4997,COMPRAS!$D$3:$D$4997,N25,COMPRAS!$B$3:$B$4997,">="&IF($C$4="",DATE(1900,1,1),$C$4),COMPRAS!$B$3:$B$4997,"<="&IF($F$4="",DATE(2999,12,31),$F$4)),0) -> 0 | Q25: =IF(N25<>"",SUMIFS(COMPRAS!$O$3:$O$4997,COMPRAS!$D$3:$D$4997,N25,COMPRAS!$B$3:$B$4997,">="&IF($C$4="",DATE(1900,1,1),$C$4),COMPRAS!$B$3:$B$4997,"<="&IF($F$4="",DATE(2999,12,31),$F$4)),0) -> 0 | S25: =PRODUCTOS!A26 -> C387 | T25: =PRODUCTOS!B26 -> BOQUERON/ BOCARTE/ ANCHOA (ANE) | U25: =IF(S25<>"",SUMIFS(COMPRAS!$J$3:$J$4997,COMPRAS!$G$3:$G$4997,S25,COMPRAS!$B$3:$B$4997,">="&IF($C$4="",DATE(1900,1,1),$C$4),COMPRAS!$B$3:$B$4997,"<="&IF($F$4="",DATE(2999,12,31),$F$4)),0) -> 48607 | V25: =IF(S25<>"",SUMIFS(COMPRAS!$O$3:$O$4997,COMPRAS!$G$3:$G$4997,S25,COMPRAS!$B$3:$B$4997,">="&IF($C$4="",DATE(1900,1,1),$C$4),COMPRAS!$B$3:$B$4997,"<="&IF($F$4="",DATE(2999,12,31),$F$4)),0) -> 74198.663 | Y25: =IF($X$2="TODOS",U25,IF(S25<>"",SUMIFS(COMPRAS!$J$3:$J$4997,COMPRAS!$G$3:$G$4997,S25,COMPRAS!$D$3:$D$4997,$X$2,COMPRAS!$B$3:$B$4997,">="&IF($C$4="",DATE(1900,1,1),$C$4),COMPRAS!$B$3:$B$4997,"<="&IF($F$4="",DATE(2999,12,31),$F$4)),0)) -> 48607 | Z25: =IF($X$2="TODOS",V25,IF(S25<>"",SUMIFS(COMPRAS!$O$3:$O$4997,COMPRAS!$G$3:$G$4997,S25,COMPRAS!$D$3:$D$4997,$X$2,COMPRAS!$B$3:$B$4997,">="&IF($C$4="",DATE(1900,1,1),$C$4),COMPRAS!$B$3:$B$4997,"<="&IF($F$4="",DATE(2999,12,31),$F$4)),0)) -> 74198.663
A26: 1 | B26: =IFERROR(INDEX($T$2:$T$231,MATCH(LARGE($U$2:$U$231,1),$U$2:$U$231,0)),"") -> BOQUERON/ BOCARTE/ ANCHOA (ANE) | C26: =IFERROR(LARGE($U$2:$U$231,1),0) -> 48607 | E26: 1 | F26: =IFERROR(INDEX($T$2:$T$231,MATCH(LARGE($V$2:$V$231,1),$V$2:$V$231,0)),"") -> BOQUERON/ BOCARTE/ ANCHOA (ANE) | G26: =IFERROR(LARGE($V$2:$V$231,1),0) -> 74198.663 | N26: =PROVEEDORES!A27 -> 50229 | O26: =PROVEEDORES!B27 -> DA LONXA O PRATO | P26: =IF(N26<>"",SUMIFS(COMPRAS!$J$3:$J$4997,COMPRAS!$D$3:$D$4997,N26,COMPRAS!$B$3:$B$4997,">="&IF($C$4="",DATE(1900,1,1),$C$4),COMPRAS!$B$3:$B$4997,"<="&IF($F$4="",DATE(2999,12,31),$F$4)),0) -> 0 | Q26: =IF(N26<>"",SUMIFS(COMPRAS!$O$3:$O$4997,COMPRAS!$D$3:$D$4997,N26,COMPRAS!$B$3:$B$4997,">="&IF($C$4="",DATE(1900,1,1),$C$4),COMPRAS!$B$3:$B$4997,"<="&IF($F$4="",DATE(2999,12,31),$F$4)),0) -> 0 | S26: =PRODUCTOS!A27 -> C822 | T26: =PRODUCTOS!B27 -> BUEY FRANCES (CRE) | U26: =IF(S26<>"",SUMIFS(COMPRAS!$J$3:$J$4997,COMPRAS!$G$3:$G$4997,S26,COMPRAS!$B$3:$B$4997,">="&IF($C$4="",DATE(1900,1,1),$C$4),COMPRAS!$B$3:$B$4997,"<="&IF($F$4="",DATE(2999,12,31),$F$4)),0) -> 0 | V26: =IF(S26<>"",SUMIFS(COMPRAS!$O$3:$O$4997,COMPRAS!$G$3:$G$4997,S26,COMPRAS!$B$3:$B$4997,">="&IF($C$4="",DATE(1900,1,1),$C$4),COMPRAS!$B$3:$B$4997,"<="&IF($F$4="",DATE(2999,12,31),$F$4)),0) -> 0 | Y26: =IF($X$2="TODOS",U26,IF(S26<>"",SUMIFS(COMPRAS!$J$3:$J$4997,COMPRAS!$G$3:$G$4997,S26,COMPRAS!$D$3:$D$4997,$X$2,COMPRAS!$B$3:$B$4997,">="&IF($C$4="",DATE(1900,1,1),$C$4),COMPRAS!$B$3:$B$4997,"<="&IF($F$4="",DATE(2999,12,31),$F$4)),0)) -> 0 | Z26: =IF($X$2="TODOS",V26,IF(S26<>"",SUMIFS(COMPRAS!$O$3:$O$4997,COMPRAS!$G$3:$G$4997,S26,COMPRAS!$D$3:$D$4997,$X$2,COMPRAS!$B$3:$B$4997,">="&IF($C$4="",DATE(1900,1,1),$C$4),COMPRAS!$B$3:$B$4997,"<="&IF($F$4="",DATE(2999,12,31),$F$4)),0)) -> 0
A27: 2 | B27: =IFERROR(INDEX($T$2:$T$231,MATCH(LARGE($U$2:$U$231,2),$U$2:$U$231,0)),"") -> LIRIO/ BACALADILLA/ PERLA (WHB) | C27: =IFERROR(LARGE($U$2:$U$231,2),0) -> 32511.65 | E27: 2 | F27: =IFERROR(INDEX($T$2:$T$231,MATCH(LARGE($V$2:$V$231,2),$V$2:$V$231,0)),"") -> LIRIO/ BACALADILLA/ PERLA (WHB) | G27: =IFERROR(LARGE($V$2:$V$231,2),0) -> 57717.359 | N27: =PROVEEDORES!A28 -> 50231 | O27: =PROVEEDORES!B28 -> PESCADOS ERNESTO Y MARIA S.L. | P27: =IF(N27<>"",SUMIFS(COMPRAS!$J$3:$J$4997,COMPRAS!$D$3:$D$4997,N27,COMPRAS!$B$3:$B$4997,">="&IF($C$4="",DATE(1900,1,1),$C$4),COMPRAS!$B$3:$B$4997,"<="&IF($F$4="",DATE(2999,12,31),$F$4)),0) -> 0 | Q27: =IF(N27<>"",SUMIFS(COMPRAS!$O$3:$O$4997,COMPRAS!$D$3:$D$4997,N27,COMPRAS!$B$3:$B$4997,">="&IF($C$4="",DATE(1900,1,1),$C$4),COMPRAS!$B$3:$B$4997,"<="&IF($F$4="",DATE(2999,12,31),$F$4)),0) -> 0 | S27: =PRODUCTOS!A28 -> C395 | T27: =PRODUCTOS!B28 -> CABALL/ SARDA/ VERDEL (MAC) | U27: =IF(S27<>"",SUMIFS(COMPRAS!$J$3:$J$4997,COMPRAS!$G$3:$G$4997,S27,COMPRAS!$B$3:$B$4997,">="&IF($C$4="",DATE(1900,1,1),$C$4),COMPRAS!$B$3:$B$4997,"<="&IF($F$4="",DATE(2999,12,31),$F$4)),0) -> 3290.95 | V27: =IF(S27<>"",SUMIFS(COMPRAS!$O$3:$O$4997,COMPRAS!$G$3:$G$4997,S27,COMPRAS!$B$3:$B$4997,">="&IF($C$4="",DATE(1900,1,1),$C$4),COMPRAS!$B$3:$B$4997,"<="&IF($F$4="",DATE(2999,12,31),$F$4)),0) -> 12989.67 | Y27: =IF($X$2="TODOS",U27,IF(S27<>"",SUMIFS(COMPRAS!$J$3:$J$4997,COMPRAS!$G$3:$G$4997,S27,COMPRAS!$D$3:$D$4997,$X$2,COMPRAS!$B$3:$B$4997,">="&IF($C$4="",DATE(1900,1,1),$C$4),COMPRAS!$B$3:$B$4997,"<="&IF($F$4="",DATE(2999,12,31),$F$4)),0)) -> 3290.95 | Z27: =IF($X$2="TODOS",V27,IF(S27<>"",SUMIFS(COMPRAS!$O$3:$O$4997,COMPRAS!$G$3:$G$4997,S27,COMPRAS!$D$3:$D$4997,$X$2,COMPRAS!$B$3:$B$4997,">="&IF($C$4="",DATE(1900,1,1),$C$4),COMPRAS!$B$3:$B$4997,"<="&IF($F$4="",DATE(2999,12,31),$F$4)),0)) -> 12989.67
A28: 3 | B28: =IFERROR(INDEX($T$2:$T$231,MATCH(LARGE($U$2:$U$231,3),$U$2:$U$231,0)),"") -> RAPE BLANCO RASCO (MON) | C28: =IFERROR(LARGE($U$2:$U$231,3),0) -> 7149.7 | E28: 3 | F28: =IFERROR(INDEX($T$2:$T$231,MATCH(LARGE($V$2:$V$231,3),$V$2:$V$231,0)),"") -> RAPE BLANCO RASCO (MON) | G28: =IFERROR(LARGE($V$2:$V$231,3),0) -> 47464.017 | N28: =PROVEEDORES!A29 -> 50232 | O28: =PROVEEDORES!B29 -> XESTION NOVA LONXA RIVEIRA S.L. | P28: =IF(N28<>"",SUMIFS(COMPRAS!$J$3:$J$4997,COMPRAS!$D$3:$D$4997,N28,COMPRAS!$B$3:$B$4997,">="&IF($C$4="",DATE(1900,1,1),$C$4),COMPRAS!$B$3:$B$4997,"<="&IF($F$4="",DATE(2999,12,31),$F$4)),0) -> 41663.771 | Q28: =IF(N28<>"",SUMIFS(COMPRAS!$O$3:$O$4997,COMPRAS!$D$3:$D$4997,N28,COMPRAS!$B$3:$B$4997,">="&IF($C$4="",DATE(1900,1,1),$C$4),COMPRAS!$B$3:$B$4997,"<="&IF($F$4="",DATE(2999,12,31),$F$4)),0) -> 101872.87 | S28: =PRODUCTOS!A29 -> C2550 | T28: =PRODUCTOS!B29 -> CABRACHO/ ESCARAPOTE (RSE) | U28: =IF(S28<>"",SUMIFS(COMPRAS!$J$3:$J$4997,COMPRAS!$G$3:$G$4997,S28,COMPRAS!$B$3:$B$4997,">="&IF($C$4="",DATE(1900,1,1),$C$4),COMPRAS!$B$3:$B$4997,"<="&IF($F$4="",DATE(2999,12,31),$F$4)),0) -> 382.5 | V28: =IF(S28<>"",SUMIFS(COMPRAS!$O$3:$O$4997,COMPRAS!$G$3:$G$4997,S28,COMPRAS!$B$3:$B$4997,">="&IF($C$4="",DATE(1900,1,1),$C$4),COMPRAS!$B$3:$B$4997,"<="&IF($F$4="",DATE(2999,12,31),$F$4)),0) -> 3663.7762 | Y28: =IF($X$2="TODOS",U28,IF(S28<>"",SUMIFS(COMPRAS!$J$3:$J$4997,COMPRAS!$G$3:$G$4997,S28,COMPRAS!$D$3:$D$4997,$X$2,COMPRAS!$B$3:$B$4997,">="&IF($C$4="",DATE(1900,1,1),$C$4),COMPRAS!$B$3:$B$4997,"<="&IF($F$4="",DATE(2999,12,31),$F$4)),0)) -> 382.5 | Z28: =IF($X$2="TODOS",V28,IF(S28<>"",SUMIFS(COMPRAS!$O$3:$O$4997,COMPRAS!$G$3:$G$4997,S28,COMPRAS!$D$3:$D$4997,$X$2,COMPRAS!$B$3:$B$4997,">="&IF($C$4="",DATE(1900,1,1),$C$4),COMPRAS!$B$3:$B$4997,"<="&IF($F$4="",DATE(2999,12,31),$F$4)),0)) -> 3663.7762
A29: 4 | B29: =IFERROR(INDEX($T$2:$T$231,MATCH(LARGE($U$2:$U$231,4),$U$2:$U$231,0)),"") -> MERLUZA EUROPEA/ FINA DIA | C29: =IFERROR(LARGE($U$2:$U$231,4),0) -> 5733.75 | E29: 4 | F29: =IFERROR(INDEX($T$2:$T$231,MATCH(LARGE($V$2:$V$231,4),$V$2:$V$231,0)),"") -> BONITO DEL NORTE 5/7 | G29: =IFERROR(LARGE($V$2:$V$231,4),0) -> 19023.43 | N29: =PROVEEDORES!A30 -> 50233 | O29: =PROVEEDORES!B30 -> ANGELPESCA S.L. | P29: =IF(N29<>"",SUMIFS(COMPRAS!$J$3:$J$4997,COMPRAS!$D$3:$D$4997,N29,COMPRAS!$B$3:$B$4997,">="&IF($C$4="",DATE(1900,1,1),$C$4),COMPRAS!$B$3:$B$4997,"<="&IF($F$4="",DATE(2999,12,31),$F$4)),0) -> 1030 | Q29: =IF(N29<>"",SUMIFS(COMPRAS!$O$3:$O$4997,COMPRAS!$D$3:$D$4997,N29,COMPRAS!$B$3:$B$4997,">="&IF($C$4="",DATE(1900,1,1),$C$4),COMPRAS!$B$3:$B$4997,"<="&IF($F$4="",DATE(2999,12,31),$F$4)),0) -> 1871.86 | S29: =PRODUCTOS!A30 -> C2552 | T29: =PRODUCTOS!B30 -> CABRACHO DE FONDO (TJX) | U29: =IF(S29<>"",SUMIFS(COMPRAS!$J$3:$J$4997,COMPRAS!$G$3:$G$4997,S29,COMPRAS!$B$3:$B$4997,">="&IF($C$4="",DATE(1900,1,1),$C$4),COMPRAS!$B$3:$B$4997,"<="&IF($F$4="",DATE(2999,12,31),$F$4)),0) -> 28.3 | V29: =IF(S29<>"",SUMIFS(COMPRAS!$O$3:$O$4997,COMPRAS!$G$3:$G$4997,S29,COMPRAS!$B$3:$B$4997,">="&IF($C$4="",DATE(1900,1,1),$C$4),COMPRAS!$B$3:$B$4997,"<="&IF($F$4="",DATE(2999,12,31),$F$4)),0) -> 144.33 | Y29: =IF($X$2="TODOS",U29,IF(S29<>"",SUMIFS(COMPRAS!$J$3:$J$4997,COMPRAS!$G$3:$G$4997,S29,COMPRAS!$D$3:$D$4997,$X$2,COMPRAS!$B$3:$B$4997,">="&IF($C$4="",DATE(1900,1,1),$C$4),COMPRAS!$B$3:$B$4997,"<="&IF($F$4="",DATE(2999,12,31),$F$4)),0)) -> 28.3 | Z29: =IF($X$2="TODOS",V29,IF(S29<>"",SUMIFS(COMPRAS!$O$3:$O$4997,COMPRAS!$G$3:$G$4997,S29,COMPRAS!$D$3:$D$4997,$X$2,COMPRAS!$B$3:$B$4997,">="&IF($C$4="",DATE(1900,1,1),$C$4),COMPRAS!$B$3:$B$4997,"<="&IF($F$4="",DATE(2999,12,31),$F$4)),0)) -> 144.33
A30: 5 | B30: =IFERROR(INDEX($T$2:$T$231,MATCH(LARGE($U$2:$U$231,5),$U$2:$U$231,0)),"") -> VARIADO PEQUEÑO | C30: =IFERROR(LARGE($U$2:$U$231,5),0) -> 4046.25 | E30: 5 | F30: =IFERROR(INDEX($T$2:$T$231,MATCH(LARGE($V$2:$V$231,5),$V$2:$V$231,0)),"") -> MERLUZA EUROPEA VOLANTA ALTURA | G30: =IFERROR(LARGE($V$2:$V$231,5),0) -> 16611.44 | N30: =PROVEEDORES!A31 -> 50235 | O30: =PROVEEDORES!B31 -> MANUEL CEBREIRA MELLA | P30: =IF(N30<>"",SUMIFS(COMPRAS!$J$3:$J$4997,COMPRAS!$D$3:$D$4997,N30,COMPRAS!$B$3:$B$4997,">="&IF($C$4="",DATE(1900,1,1),$C$4),COMPRAS!$B$3:$B$4997,"<="&IF($F$4="",DATE(2999,12,31),$F$4)),0) -> 0 | Q30: =IF(N30<>"",SUMIFS(COMPRAS!$O$3:$O$4997,COMPRAS!$D$3:$D$4997,N30,COMPRAS!$B$3:$B$4997,">="&IF($C$4="",DATE(1900,1,1),$C$4),COMPRAS!$B$3:$B$4997,"<="&IF($F$4="",DATE(2999,12,31),$F$4)),0) -> 0 | S30: =PRODUCTOS!A31 -> C255 | T30: =PRODUCTOS!B31 -> CABRAS/ GALLINETA (BRF) | U30: =IF(S30<>"",SUMIFS(COMPRAS!$J$3:$J$4997,COMPRAS!$G$3:$G$4997,S30,COMPRAS!$B$3:$B$4997,">="&IF($C$4="",DATE(1900,1,1),$C$4),COMPRAS!$B$3:$B$4997,"<="&IF($F$4="",DATE(2999,12,31),$F$4)),0) -> 1265.3 | V30: =IF(S30<>"",SUMIFS(COMPRAS!$O$3:$O$4997,COMPRAS!$G$3:$G$4997,S30,COMPRAS!$B$3:$B$4997,">="&IF($C$4="",DATE(1900,1,1),$C$4),COMPRAS!$B$3:$B$4997,"<="&IF($F$4="",DATE(2999,12,31),$F$4)),0) -> 8640.443 | Y30: =IF($X$2="TODOS",U30,IF(S30<>"",SUMIFS(COMPRAS!$J$3:$J$4997,COMPRAS!$G$3:$G$4997,S30,COMPRAS!$D$3:$D$4997,$X$2,COMPRAS!$B$3:$B$4997,">="&IF($C$4="",DATE(1900,1,1),$C$4),COMPRAS!$B$3:$B$4997,"<="&IF($F$4="",DATE(2999,12,31),$F$4)),0)) -> 1265.3 | Z30: =IF($X$2="TODOS",V30,IF(S30<>"",SUMIFS(COMPRAS!$O$3:$O$4997,COMPRAS!$G$3:$G$4997,S30,COMPRAS!$D$3:$D$4997,$X$2,COMPRAS!$B$3:$B$4997,">="&IF($C$4="",DATE(1900,1,1),$C$4),COMPRAS!$B$3:$B$4997,"<="&IF($F$4="",DATE(2999,12,31),$F$4)),0)) -> 8640.443
A31: 6 | B31: =IFERROR(INDEX($T$2:$T$231,MATCH(LARGE($U$2:$U$231,6),$U$2:$U$231,0)),"") -> BONITO DEL NORTE 5/7 | C31: =IFERROR(LARGE($U$2:$U$231,6),0) -> 3944.05 | E31: 6 | F31: =IFERROR(INDEX($T$2:$T$231,MATCH(LARGE($V$2:$V$231,6),$V$2:$V$231,0)),"") -> MERLUZA EUROPEA/ FINA DIA | G31: =IFERROR(LARGE($V$2:$V$231,6),0) -> 16382.407 | N31: =PROVEEDORES!A32 -> 50236 | O31: =PROVEEDORES!B32 -> CASIMIRO PEREZ RODRIGUEZ | P31: =IF(N31<>"",SUMIFS(COMPRAS!$J$3:$J$4997,COMPRAS!$D$3:$D$4997,N31,COMPRAS!$B$3:$B$4997,">="&IF($C$4="",DATE(1900,1,1),$C$4),COMPRAS!$B$3:$B$4997,"<="&IF($F$4="",DATE(2999,12,31),$F$4)),0) -> 0 | Q31: =IF(N31<>"",SUMIFS(COMPRAS!$O$3:$O$4997,COMPRAS!$D$3:$D$4997,N31,COMPRAS!$B$3:$B$4997,">="&IF($C$4="",DATE(1900,1,1),$C$4),COMPRAS!$B$3:$B$4997,"<="&IF($F$4="",DATE(2999,12,31),$F$4)),0) -> 0 | S31: =PRODUCTOS!A32 -> C258 | T31: =PRODUCTOS!B32 -> CABRILLAS/ SERRANO (CBR) | U31: =IF(S31<>"",SUMIFS(COMPRAS!$J$3:$J$4997,COMPRAS!$G$3:$G$4997,S31,COMPRAS!$B$3:$B$4997,">="&IF($C$4="",DATE(1900,1,1),$C$4),COMPRAS!$B$3:$B$4997,"<="&IF($F$4="",DATE(2999,12,31),$F$4)),0) -> 0 | V31: =IF(S31<>"",SUMIFS(COMPRAS!$O$3:$O$4997,COMPRAS!$G$3:$G$4997,S31,COMPRAS!$B$3:$B$4997,">="&IF($C$4="",DATE(1900,1,1),$C$4),COMPRAS!$B$3:$B$4997,"<="&IF($F$4="",DATE(2999,12,31),$F$4)),0) -> 0 | Y31: =IF($X$2="TODOS",U31,IF(S31<>"",SUMIFS(COMPRAS!$J$3:$J$4997,COMPRAS!$G$3:$G$4997,S31,COMPRAS!$D$3:$D$4997,$X$2,COMPRAS!$B$3:$B$4997,">="&IF($C$4="",DATE(1900,1,1),$C$4),COMPRAS!$B$3:$B$4997,"<="&IF($F$4="",DATE(2999,12,31),$F$4)),0)) -> 0 | Z31: =IF($X$2="TODOS",V31,IF(S31<>"",SUMIFS(COMPRAS!$O$3:$O$4997,COMPRAS!$G$3:$G$4997,S31,COMPRAS!$D$3:$D$4997,$X$2,COMPRAS!$B$3:$B$4997,">="&IF($C$4="",DATE(1900,1,1),$C$4),COMPRAS!$B$3:$B$4997,"<="&IF($F$4="",DATE(2999,12,31),$F$4)),0)) -> 0
A32: 7 | B32: =IFERROR(INDEX($T$2:$T$231,MATCH(LARGE($U$2:$U$231,7),$U$2:$U$231,0)),"") -> MERLUZA EUROPEA ARRASTRE (HKE) | C32: =IFERROR(LARGE($U$2:$U$231,7),0) -> 3583.45 | E32: 7 | F32: =IFERROR(INDEX($T$2:$T$231,MATCH(LARGE($V$2:$V$231,7),$V$2:$V$231,0)),"") -> LUBINA RIA/ ROBALIZA (BSS) | G32: =IFERROR(LARGE($V$2:$V$231,7),0) -> 16171.083 | N32: =PROVEEDORES!A33 -> 50509 | O32: =PROVEEDORES!B33 -> AZORFISK UNIPERSONAL LDA | P32: =IF(N32<>"",SUMIFS(COMPRAS!$J$3:$J$4997,COMPRAS!$D$3:$D$4997,N32,COMPRAS!$B$3:$B$4997,">="&IF($C$4="",DATE(1900,1,1),$C$4),COMPRAS!$B$3:$B$4997,"<="&IF($F$4="",DATE(2999,12,31),$F$4)),0) -> 479.4 | Q32: =IF(N32<>"",SUMIFS(COMPRAS!$O$3:$O$4997,COMPRAS!$D$3:$D$4997,N32,COMPRAS!$B$3:$B$4997,">="&IF($C$4="",DATE(1900,1,1),$C$4),COMPRAS!$B$3:$B$4997,"<="&IF($F$4="",DATE(2999,12,31),$F$4)),0) -> 14685.925 | S32: =PRODUCTOS!A33 -> C710 | T32: =PRODUCTOS!B33 -> CALAAMR COMUN (SQR) | U32: =IF(S32<>"",SUMIFS(COMPRAS!$J$3:$J$4997,COMPRAS!$G$3:$G$4997,S32,COMPRAS!$B$3:$B$4997,">="&IF($C$4="",DATE(1900,1,1),$C$4),COMPRAS!$B$3:$B$4997,"<="&IF($F$4="",DATE(2999,12,31),$F$4)),0) -> 113.7 | V32: =IF(S32<>"",SUMIFS(COMPRAS!$O$3:$O$4997,COMPRAS!$G$3:$G$4997,S32,COMPRAS!$B$3:$B$4997,">="&IF($C$4="",DATE(1900,1,1),$C$4),COMPRAS!$B$3:$B$4997,"<="&IF($F$4="",DATE(2999,12,31),$F$4)),0) -> 1882.135 | Y32: =IF($X$2="TODOS",U32,IF(S32<>"",SUMIFS(COMPRAS!$J$3:$J$4997,COMPRAS!$G$3:$G$4997,S32,COMPRAS!$D$3:$D$4997,$X$2,COMPRAS!$B$3:$B$4997,">="&IF($C$4="",DATE(1900,1,1),$C$4),COMPRAS!$B$3:$B$4997,"<="&IF($F$4="",DATE(2999,12,31),$F$4)),0)) -> 113.7 | Z32: =IF($X$2="TODOS",V32,IF(S32<>"",SUMIFS(COMPRAS!$O$3:$O$4997,COMPRAS!$G$3:$G$4997,S32,COMPRAS!$D$3:$D$4997,$X$2,COMPRAS!$B$3:$B$4997,">="&IF($C$4="",DATE(1900,1,1),$C$4),COMPRAS!$B$3:$B$4997,"<="&IF($F$4="",DATE(2999,12,31),$F$4)),0)) -> 1882.135
A33: 8 | B33: =IFERROR(INDEX($T$2:$T$231,MATCH(LARGE($U$2:$U$231,8),$U$2:$U$231,0)),"") -> CABALL/ SARDA/ VERDEL (MAC) | C33: =IFERROR(LARGE($U$2:$U$231,8),0) -> 3290.95 | E33: 8 | F33: =IFERROR(INDEX($T$2:$T$231,MATCH(LARGE($V$2:$V$231,8),$V$2:$V$231,0)),"") -> MERLUZA EUROPEA PINCHO COSTA 800 | G33: =IFERROR(LARGE($V$2:$V$231,8),0) -> 13944.356 | N33: =PROVEEDORES!A34 -> 50510 | O33: =PROVEEDORES!B34 -> PETACA CHICO S.L. | P33: =IF(N33<>"",SUMIFS(COMPRAS!$J$3:$J$4997,COMPRAS!$D$3:$D$4997,N33,COMPRAS!$B$3:$B$4997,">="&IF($C$4="",DATE(1900,1,1),$C$4),COMPRAS!$B$3:$B$4997,"<="&IF($F$4="",DATE(2999,12,31),$F$4)),0) -> 126.7 | Q33: =IF(N33<>"",SUMIFS(COMPRAS!$O$3:$O$4997,COMPRAS!$D$3:$D$4997,N33,COMPRAS!$B$3:$B$4997,">="&IF($C$4="",DATE(1900,1,1),$C$4),COMPRAS!$B$3:$B$4997,"<="&IF($F$4="",DATE(2999,12,31),$F$4)),0) -> 2416.09 | S33: =PRODUCTOS!A34 -> C730 | T33: =PRODUCTOS!B34 -> CALAMAR PATAGONICO (SQP) | U33: =IF(S33<>"",SUMIFS(COMPRAS!$J$3:$J$4997,COMPRAS!$G$3:$G$4997,S33,COMPRAS!$B$3:$B$4997,">="&IF($C$4="",DATE(1900,1,1),$C$4),COMPRAS!$B$3:$B$4997,"<="&IF($F$4="",DATE(2999,12,31),$F$4)),0) -> 0 | V33: =IF(S33<>"",SUMIFS(COMPRAS!$O$3:$O$4997,COMPRAS!$G$3:$G$4997,S33,COMPRAS!$B$3:$B$4997,">="&IF($C$4="",DATE(1900,1,1),$C$4),COMPRAS!$B$3:$B$4997,"<="&IF($F$4="",DATE(2999,12,31),$F$4)),0) -> 0 | Y33: =IF($X$2="TODOS",U33,IF(S33<>"",SUMIFS(COMPRAS!$J$3:$J$4997,COMPRAS!$G$3:$G$4997,S33,COMPRAS!$D$3:$D$4997,$X$2,COMPRAS!$B$3:$B$4997,">="&IF($C$4="",DATE(1900,1,1),$C$4),COMPRAS!$B$3:$B$4997,"<="&IF($F$4="",DATE(2999,12,31),$F$4)),0)) -> 0 | Z33: =IF($X$2="TODOS",V33,IF(S33<>"",SUMIFS(COMPRAS!$O$3:$O$4997,COMPRAS!$G$3:$G$4997,S33,COMPRAS!$D$3:$D$4997,$X$2,COMPRAS!$B$3:$B$4997,">="&IF($C$4="",DATE(1900,1,1),$C$4),COMPRAS!$B$3:$B$4997,"<="&IF($F$4="",DATE(2999,12,31),$F$4)),0)) -> 0
A34: 9 | B34: =IFERROR(INDEX($T$2:$T$231,MATCH(LARGE($U$2:$U$231,9),$U$2:$U$231,0)),"") -> MERLUZA EUROPEA PINCHO COSTA 800 | C34: =IFERROR(LARGE($U$2:$U$231,9),0) -> 2398.55 | E34: 9 | F34: =IFERROR(INDEX($T$2:$T$231,MATCH(LARGE($V$2:$V$231,9),$V$2:$V$231,0)),"") -> MERLUZA EUROPEA PINCHO COSTA | G34: =IFERROR(LARGE($V$2:$V$231,9),0) -> 13017.643 | N34: =PROVEEDORES!A35 -> 50511 | O34: =PROVEEDORES!B35 -> PESCADO JAMARDO S.L | P34: =IF(N34<>"",SUMIFS(COMPRAS!$J$3:$J$4997,COMPRAS!$D$3:$D$4997,N34,COMPRAS!$B$3:$B$4997,">="&IF($C$4="",DATE(1900,1,1),$C$4),COMPRAS!$B$3:$B$4997,"<="&IF($F$4="",DATE(2999,12,31),$F$4)),0) -> 0 | Q34: =IF(N34<>"",SUMIFS(COMPRAS!$O$3:$O$4997,COMPRAS!$D$3:$D$4997,N34,COMPRAS!$B$3:$B$4997,">="&IF($C$4="",DATE(1900,1,1),$C$4),COMPRAS!$B$3:$B$4997,"<="&IF($F$4="",DATE(2999,12,31),$F$4)),0) -> 0 | S34: =PRODUCTOS!A35 -> C720 | T34: =PRODUCTOS!B35 -> CALAMAR VETADO/ FORBES (SQF) | U34: =IF(S34<>"",SUMIFS(COMPRAS!$J$3:$J$4997,COMPRAS!$G$3:$G$4997,S34,COMPRAS!$B$3:$B$4997,">="&IF($C$4="",DATE(1900,1,1),$C$4),COMPRAS!$B$3:$B$4997,"<="&IF($F$4="",DATE(2999,12,31),$F$4)),0) -> 59.7 | V34: =IF(S34<>"",SUMIFS(COMPRAS!$O$3:$O$4997,COMPRAS!$G$3:$G$4997,S34,COMPRAS!$B$3:$B$4997,">="&IF($C$4="",DATE(1900,1,1),$C$4),COMPRAS!$B$3:$B$4997,"<="&IF($F$4="",DATE(2999,12,31),$F$4)),0) -> 1008.2 | Y34: =IF($X$2="TODOS",U34,IF(S34<>"",SUMIFS(COMPRAS!$J$3:$J$4997,COMPRAS!$G$3:$G$4997,S34,COMPRAS!$D$3:$D$4997,$X$2,COMPRAS!$B$3:$B$4997,">="&IF($C$4="",DATE(1900,1,1),$C$4),COMPRAS!$B$3:$B$4997,"<="&IF($F$4="",DATE(2999,12,31),$F$4)),0)) -> 59.7 | Z34: =IF($X$2="TODOS",V34,IF(S34<>"",SUMIFS(COMPRAS!$O$3:$O$4997,COMPRAS!$G$3:$G$4997,S34,COMPRAS!$D$3:$D$4997,$X$2,COMPRAS!$B$3:$B$4997,">="&IF($C$4="",DATE(1900,1,1),$C$4),COMPRAS!$B$3:$B$4997,"<="&IF($F$4="",DATE(2999,12,31),$F$4)),0)) -> 1008.2
A35: 10 | B35: =IFERROR(INDEX($T$2:$T$231,MATCH(LARGE($U$2:$U$231,10),$U$2:$U$231,0)),"") -> RAPE NEGRO (ANK) | C35: =IFERROR(LARGE($U$2:$U$231,10),0) -> 2166.3 | E35: 10 | F35: =IFERROR(INDEX($T$2:$T$231,MATCH(LARGE($V$2:$V$231,10),$V$2:$V$231,0)),"") -> CABALL/ SARDA/ VERDEL (MAC) | G35: =IFERROR(LARGE($V$2:$V$231,10),0) -> 12989.67 | N35: =PROVEEDORES!A36 -> 50512 | O35: =PROVEEDORES!B36 -> MAR IMPORT VENTA S.L. | P35: =IF(N35<>"",SUMIFS(COMPRAS!$J$3:$J$4997,COMPRAS!$D$3:$D$4997,N35,COMPRAS!$B$3:$B$4997,">="&IF($C$4="",DATE(1900,1,1),$C$4),COMPRAS!$B$3:$B$4997,"<="&IF($F$4="",DATE(2999,12,31),$F$4)),0) -> 0 | Q35: =IF(N35<>"",SUMIFS(COMPRAS!$O$3:$O$4997,COMPRAS!$D$3:$D$4997,N35,COMPRAS!$B$3:$B$4997,">="&IF($C$4="",DATE(1900,1,1),$C$4),COMPRAS!$B$3:$B$4997,"<="&IF($F$4="",DATE(2999,12,31),$F$4)),0) -> 0 | S35: =PRODUCTOS!A36 -> C823 | T35: =PRODUCTOS!B36 -> CENTOLLA/ CENTOLLO (SCR) | U35: =IF(S35<>"",SUMIFS(COMPRAS!$J$3:$J$4997,COMPRAS!$G$3:$G$4997,S35,COMPRAS!$B$3:$B$4997,">="&IF($C$4="",DATE(1900,1,1),$C$4),COMPRAS!$B$3:$B$4997,"<="&IF($F$4="",DATE(2999,12,31),$F$4)),0) -> 0 | V35: =IF(S35<>"",SUMIFS(COMPRAS!$O$3:$O$4997,COMPRAS!$G$3:$G$4997,S35,COMPRAS!$B$3:$B$4997,">="&IF($C$4="",DATE(1900,1,1),$C$4),COMPRAS!$B$3:$B$4997,"<="&IF($F$4="",DATE(2999,12,31),$F$4)),0) -> 0 | Y35: =IF($X$2="TODOS",U35,IF(S35<>"",SUMIFS(COMPRAS!$J$3:$J$4997,COMPRAS!$G$3:$G$4997,S35,COMPRAS!$D$3:$D$4997,$X$2,COMPRAS!$B$3:$B$4997,">="&IF($C$4="",DATE(1900,1,1),$C$4),COMPRAS!$B$3:$B$4997,"<="&IF($F$4="",DATE(2999,12,31),$F$4)),0)) -> 0 | Z35: =IF($X$2="TODOS",V35,IF(S35<>"",SUMIFS(COMPRAS!$O$3:$O$4997,COMPRAS!$G$3:$G$4997,S35,COMPRAS!$D$3:$D$4997,$X$2,COMPRAS!$B$3:$B$4997,">="&IF($C$4="",DATE(1900,1,1),$C$4),COMPRAS!$B$3:$B$4997,"<="&IF($F$4="",DATE(2999,12,31),$F$4)),0)) -> 0
